Workbook

Sheet О книге
A1: Книга | B1: ASTM D86 расчёт (группы 1-4)
A2: Версия | B2: 3.11.0
A3: Дата генерации | B3: 2026-10-07
A4: Стандарт | B4: ASTM D86-20a (группы 1-4)
A5: Метод | B5: Определение фракционного состава при атмосферном давлении
A6: Источник расчёта | B6: fraction_lib (Python)
A7: Автор/Разработчик | B7: лаборатория (заполнить)
A8: Проверил
A9: Утвердил
A10: Примечание | B10: Книга генерируется скриптом — правки вручную не вносить
A11: Политика пустых ячеек (TD-007) | B11: Пустая ячейка = не введено (НЕ РАССЧИТАНО). Ошибка формулы = ошибка расчёта. Статус контроля: НЕ РАССЧИТАНО / OK / НЕ СООТВЕТСТВУЕТ.
A12: Критерий K (ГСО) | B12: K = (1/√2)·√(R² − r²/2) — из свидетельства на ГСО, НЕ изменять
A13: Коэффициент 0,84 (ОК) | B13: Из сборника «Метрология в химическом анализе» (АНАЛИТИКА), НЕ изменять

Sheet Ввод
A1: Атмосферное давление, мм рт.ст. | B1: 755 | C1: Группа (1-4) | D1: 4 | F1: Объём образца, мл | G1: 100
A3: % отгона | B3: V, мл | C3: T1, °C | D3: T2, °C | E3: Потери, % | F3: Остаток, % | G3: Отгон, %
A4: =IF(ISNUMBER(B4),ROUND(B4/$G$1*100,1),"НК") -> 0 | B4: 0 | C4: 161.75 | D4: 161.75
A5: =IF(ISNUMBER(B5),ROUND(B5/$G$1*100,1),"5") -> 5 | B5: 5 | C5: 190.5 | D5: 190.5
A6: =IF(ISNUMBER(B6),ROUND(B6/$G$1*100,1),"10") -> 10 | B6: 10 | C6: 203.75 | D6: 203.75
A7: =IF(ISNUMBER(B7),ROUND(B7/$G$1*100,1),"15") -> 15 | B7: 15 | C7: 210 | D7: 210
A8: =IF(ISNUMBER(B8),ROUND(B8/$G$1*100,1),"20") -> 20 | B8: 20 | C8: 227.5 | D8: 227.5
A9: =IF(ISNUMBER(B9),ROUND(B9/$G$1*100,1),"25") -> 25 | B9: 25 | C9: 235 | D9: 235
A10: =IF(ISNUMBER(B10),ROUND(B10/$G$1*100,1),"30") -> 30 | B10: 30 | C10: 244 | D10: 244
A11: =IF(ISNUMBER(B11),ROUND(B11/$G$1*100,1),"35") -> 35 | B11: 35 | C11: 250 | D11: 250
A12: =IF(ISNUMBER(B12),ROUND(B12/$G$1*100,1),"40") -> 40 | B12: 40 | C12: 256.5 | D12: 256.5
A13: =IF(ISNUMBER(B13),ROUND(B13/$G$1*100,1),"45") -> 45 | B13: 45 | C13: 262 | D13: 262
A14: =IF(ISNUMBER(B14),ROUND(B14/$G$1*100,1),"50") -> 50 | B14: 50 | C14: 268.75 | D14: 268.75
A15: =IF(ISNUMBER(B15),ROUND(B15/$G$1*100,1),"55") -> 55 | B15: 55 | C15: 274 | D15: 274
A16: =IF(ISNUMBER(B16),ROUND(B16/$G$1*100,1),"60") -> 60 | B16: 60 | C16: 280.5 | D16: 280.5
A17: =IF(ISNUMBER(B17),ROUND(B17/$G$1*100,1),"65") -> 65 | B17: 65 | C17: 287 | D17: 287
A18: =IF(ISNUMBER(B18),ROUND(B18/$G$1*100,1),"70") -> 70 | B18: 70 | C18: 293.75 | D18: 293.75
A19: =IF(ISNUMBER(B19),ROUND(B19/$G$1*100,1),"75") -> 75 | B19: 75 | C19: 300 | D19: 300
A20: =IF(ISNUMBER(B20),ROUND(B20/$G$1*100,1),"80") -> 80 | B20: 80 | C20: 309.25 | D20: 309.25
A21: =IF(ISNUMBER(B21),ROUND(B21/$G$1*100,1),"85") -> 85 | B21: 85 | C21: 318 | D21: 318
A22: =IF(ISNUMBER(B22),ROUND(B22/$G$1*100,1),"90") -> 90 | B22: 90 | C22: 329.75 | D22: 329.75
A23: =IF(ISNUMBER(B23),ROUND(B23/$G$1*100,1),"95") -> 95 | B23: 95 | C23: 345.25 | D23: 345.25
A24: =IF(ISNUMBER(B24),ROUND(B24/$G$1*100,1),"КК") -> 100 | B24: 100 | C24: 355 | D24: 355
E25: 0.5 | F25: 1.5 | G25: =100-E25-F25 -> 98
A26: Проверка входных данных:
A28: Монотонность 1% -> 2% | B28: =IF(OR(ISBLANK(C4),ISBLANK(C5)),"",IF(C5>=B4,"OK","НАРУШЕНА")) -> OK
A29: Монотонность 2% -> 3% | B29: =IF(OR(ISBLANK(C5),ISBLANK(C6)),"",IF(C6>=B5,"OK","НАРУШЕНА")) -> OK
A30: Монотонность 3% -> 4% | B30: =IF(OR(ISBLANK(C6),ISBLANK(C7)),"",IF(C7>=B6,"OK","НАРУШЕНА")) -> OK
A31: Монотонность 4% -> 5% | B31: =IF(OR(ISBLANK(C7),ISBLANK(C8)),"",IF(C8>=B7,"OK","НАРУШЕНА")) -> OK
A32: Монотонность 5% -> 6% | B32: =IF(OR(ISBLANK(C8),ISBLANK(C9)),"",IF(C9>=B8,"OK","НАРУШЕНА")) -> OK
A33: Монотонность 6% -> 7% | B33: =IF(OR(ISBLANK(C9),ISBLANK(C10)),"",IF(C10>=B9,"OK","НАРУШЕНА")) -> OK
A34: Монотонность 7% -> 8% | B34: =IF(OR(ISBLANK(C10),ISBLANK(C11)),"",IF(C11>=B10,"OK","НАРУШЕНА")) -> OK
A35: Монотонность 8% -> 9% | B35: =IF(OR(ISBLANK(C11),ISBLANK(C12)),"",IF(C12>=B11,"OK","НАРУШЕНА")) -> OK
A36: Монотонность 9% -> 10% | B36: =IF(OR(ISBLANK(C12),ISBLANK(C13)),"",IF(C13>=B12,"OK","НАРУШЕНА")) -> OK
A37: Монотонность 10% -> 11% | B37: =IF(OR(ISBLANK(C13),ISBLANK(C14)),"",IF(C14>=B13,"OK","НАРУШЕНА")) -> OK
A38: Монотонность 11% -> 12% | B38: =IF(OR(ISBLANK(C14),ISBLANK(C15)),"",IF(C15>=B14,"OK","НАРУШЕНА")) -> OK
A39: Монотонность 12% -> 13% | B39: =IF(OR(ISBLANK(C15),ISBLANK(C16)),"",IF(C16>=B15,"OK","НАРУШЕНА")) -> OK
A40: Монотонность 13% -> 14% | B40: =IF(OR(ISBLANK(C16),ISBLANK(C17)),"",IF(C17>=B16,"OK","НАРУШЕНА")) -> OK
A41: Баланс (отгон+потери+остаток) | B41: =IF(ABS(A24+E25+F25-100)<0.2,"OK","НАРУШЕН") -> НАРУШЕН
A42: Примечание: пустые температуры не нарушение | B42: =IF(OR(ISBLANK(C18),ISBLANK(C19)),"",IF(C19>=B18,"OK","НАРУШЕНА")) -> OK
...

Sheet Расчёт
A1: % отгона | B1: T1 | C1: T2 | D1: Хср | E1: Поправка Янга | F1: T_corr | G1: Потери (защ.) | H1: |T1-T2| | I1: r | J1: R | K1: K (ГСО) | L1: 0.84R (ОК) | M1: Крутизна S | N1: Статус | O1: % выпаривания (Pe) | Q1: ВЕТКА 1 — ЗАДАНЫ ОБЪЁМЫ (выпаривание): % отгона → T1/T2 → поправка давления → T_corr (приведена к 760). Ввод: T1/T2 и объёмы в «Ввод» (зелёные ячейки), Ввод!$G$1 = объём образца, мл.
A2: 0 | B2: =Ввод!C4 -> 161.75 | C2: =Ввод!D4 -> 161.75 | D2: =IF(OR(ISBLANK(B2),ISBLANK(C2)),B2,MROUND((B2+C2)/2,0.5)) -> 162 | E2: =0.00012*(760-Ввод!$B$1)*(273+D2) -> 0.261 | F2: =IF(ISBLANK(D2),"",MROUND(D2+E2,0.5)) -> 162.5 | G2: =IF(Ввод!$B$1>760,Ввод!E25,0.5+(Ввод!E25-0.5)/(1+(760-Ввод!$B$1)/60)) -> 0.5 | H2: =IF(OR(ISBLANK(B2),ISBLANK(C2)),"",ABS(B2-C2)) -> 0 | I2: =IF(Ввод!$D$1=1,3.3,0.35*M2+1) -> 2.995 | J2: =IF(Ввод!$D$1=1,5.6,0.93*M2+2.8) -> 8.101 | K2: =(1/SQRT(2))*SQRT(J2^2-I2^2/2) -> 5.5290681 | L2: =0.84*J2 -> 6.80484 | M2: =IF(OR(ISBLANK(F2),ISBLANK(F3)),"",ABS(F3-F2)/5) -> 5.7 | N2: =IF(OR(ISBLANK(B2),ISBLANK(C2)),"НЕ РАССЧИТАНО",IF(AND(ISNUMBER(H2),ISNUMBER(I2)),IF(H2<=I2,"OK","НЕ СООТВЕТСТВУЕТ"),"НЕ РАССЧИТАНО")) -> OK | O2: =IF(ISNUMBER(A2),IF(Ввод!$D$1=1,ROUND(A2+G2,1),A2),"") -> 0
A3: 5 | B3: =Ввод!C5 -> 190.5 | C3: =Ввод!D5 -> 190.5 | D3: =IF(OR(ISBLANK(B3),ISBLANK(C3)),B3,MROUND((B3+C3)/2,0.5)) -> 190.5 | E3: =0.00012*(760-Ввод!$B$1)*(273+D3) -> 0.2781 | F3: =IF(ISBLANK(D3),"",MROUND(D3+E3,0.5)) -> 191 | G3: =IF(Ввод!$B$1>760,Ввод!E25,0.5+(Ввод!E25-0.5)/(1+(760-Ввод!$B$1)/60)) -> 0.5 | H3: =IF(OR(ISBLANK(B3),ISBLANK(C3)),"",ABS(B3-C3)) -> 0 | I3: =IF(Ввод!$D$1=1,1.9+0.86*M3,1+0.41*M3) -> 2.722 | J3: =IF(Ввод!$D$1=1,3.1+1.74*M3,1.8+1.33*M3) -> 7.386 | K3: =(1/SQRT(2))*SQRT(J3^2-I3^2/2) -> 5.0422393 | L3: =0.84*J3 -> 6.20424 | M3: =IF(OR(ISBLANK(F2),ISBLANK(F4)),"",ABS(F4-F2)/(A4-A2)) -> 4.2 | N3: =IF(OR(ISBLANK(B3),ISBLANK(C3)),"НЕ РАССЧИТАНО",IF(AND(ISNUMBER(H3),ISNUMBER(I3)),IF(H3<=I3,"OK","НЕ СООТВЕТСТВУЕТ"),"НЕ РАССЧИТАНО")) -> OK | O3: =IF(ISNUMBER(A3),IF(Ввод!$D$1=1,ROUND(A3+G3,1),A3),"") -> 5
A4: 10 | B4: =Ввод!C6 -> 203.75 | C4: =Ввод!D6 -> 203.75 | D4: =IF(OR(ISBLANK(B4),ISBLANK(C4)),B4,MROUND((B4+C4)/2,0.5)) -> 204 | E4: =0.00012*(760-Ввод!$B$1)*(273+D4) -> 0.2862 | F4: =IF(ISBLANK(D4),"",MROUND(D4+E4,0.5)) -> 204.5 | G4: =IF(Ввод!$B$1>760,Ввод!E25,0.5+(Ввод!E25-0.5)/(1+(760-Ввод!$B$1)/60)) -> 0.5 | H4: =IF(OR(ISBLANK(B4),ISBLANK(C4)),"",ABS(B4-C4)) -> 0 | I4: =IF(Ввод!$D$1=1,1.2+0.86*M4,1+0.41*M4) -> 1.7995 | J4: =IF(Ввод!$D$1=1,2+1.74*M4,1.8+1.33*M4) -> 4.3935 | K4: =(1/SQRT(2))*SQRT(J4^2-I4^2/2) -> 2.9735284 | L4: =0.84*J4 -> 3.69054 | M4: =IF(OR(ISBLANK(F3),ISBLANK(F5)),"",ABS(F5-F3)/(A5-A3)) -> 1.95 | N4: =IF(OR(ISBLANK(B4),ISBLANK(C4)),"НЕ РАССЧИТАНО",IF(AND(ISNUMBER(H4),ISNUMBER(I4)),IF(H4<=I4,"OK","НЕ СООТВЕТСТВУЕТ"),"НЕ РАССЧИТАНО")) -> OK | O4: =IF(ISNUMBER(A4),IF(Ввод!$D$1=1,ROUND(A4+G4,1),A4),"") -> 10
A5: 15 | B5: =Ввод!C7 -> 210 | C5: =Ввод!D7 -> 210 | D5: =IF(OR(ISBLANK(B5),ISBLANK(C5)),B5,MROUND((B5+C5)/2,0.5)) -> 210 | E5: =0.00012*(760-Ввод!$B$1)*(273+D5) -> 0.2898 | F5: =IF(ISBLANK(D5),"",MROUND(D5+E5,0.5)) -> 210.5 | G5: =IF(Ввод!$B$1>760,Ввод!E25,0.5+(Ввод!E25-0.5)/(1+(760-Ввод!$B$1)/60)) -> 0.5 | H5: =IF(OR(ISBLANK(B5),ISBLANK(C5)),"",ABS(B5-C5)) -> 0 | I5: =IF(Ввод!$D$1=1,1.2+0.86*M5,1+0.41*M5) -> 1.9635 | J5: =IF(Ввод!$D$1=1,2+1.74*M5,1.8+1.33*M5) -> 4.9255 | K5: =(1/SQRT(2))*SQRT(J5^2-I5^2/2) -> 3.3416227 | L5: =0.84*J5 -> 4.13742 | M5: =IF(OR(ISBLANK(F4),ISBLANK(F6)),"",ABS(F6-F4)/(A6-A4)) -> 2.35 | N5: =IF(OR(ISBLANK(B5),ISBLANK(C5)),"НЕ РАССЧИТАНО",IF(AND(ISNUMBER(H5),ISNUMBER(I5)),IF(H5<=I5,"OK","НЕ СООТВЕТСТВУЕТ"),"НЕ РАССЧИТАНО")) -> OK | O5: =IF(ISNUMBER(A5),IF(Ввод!$D$1=1,ROUND(A5+G5,1),A5),"") -> 15
A6: 20 | B6: =Ввод!C8 -> 227.5 | C6: =Ввод!D8 -> 227.5 | D6: =IF(OR(ISBLANK(B6),ISBLANK(C6)),B6,MROUND((B6+C6)/2,0.5)) -> 227.5 | E6: =0.00012*(760-Ввод!$B$1)*(273+D6) -> 0.3003 | F6: =IF(ISBLANK(D6),"",MROUND(D6+E6,0.5)) -> 228 | G6: =IF(Ввод!$B$1>760,Ввод!E25,0.5+(Ввод!E25-0.5)/(1+(760-Ввод!$B$1)/60)) -> 0.5 | H6: =IF(OR(ISBLANK(B6),ISBLANK(C6)),"",ABS(B6-C6)) -> 0 | I6: =IF(Ввод!$D$1=1,1.2+0.86*M6,1+0.41*M6) -> 2.025 | J6: =IF(Ввод!$D$1=1,2+1.74*M6,1.8+1.33*M6) -> 5.125 | K6: =(1/SQRT(2))*SQRT(J6^2-I6^2/2) -> 3.4796058 | L6: =0.84*J6 -> 4.305 | M6: =IF(OR(ISBLANK(F5),ISBLANK(F7)),"",ABS(F7-F5)/(A7-A5)) -> 2.5 | N6: =IF(OR(ISBLANK(B6),ISBLANK(C6)),"НЕ РАССЧИТАНО",IF(AND(ISNUMBER(H6),ISNUMBER(I6)),IF(H6<=I6,"OK","НЕ СООТВЕТСТВУЕТ"),"НЕ РАССЧИТАНО")) -> OK | O6: =IF(ISNUMBER(A6),IF(Ввод!$D$1=1,ROUND(A6+G6,1),A6),"") -> 20
A7: 25 | B7: =Ввод!C9 -> 235 | C7: =Ввод!D9 -> 235 | D7: =IF(OR(ISBLANK(B7),ISBLANK(C7)),B7,MROUND((B7+C7)/2,0.5)) -> 235 | E7: =0.00012*(760-Ввод!$B$1)*(273+D7) -> 0.3048 | F7: =IF(ISBLANK(D7),"",MROUND(D7+E7,0.5)) -> 235.5 | G7: =IF(Ввод!$B$1>760,Ввод!E25,0.5+(Ввод!E25-0.5)/(1+(760-Ввод!$B$1)/60)) -> 0.5 | H7: =IF(OR(ISBLANK(B7),ISBLANK(C7)),"",ABS(B7-C7)) -> 0 | I7: =IF(Ввод!$D$1=1,1.2+0.86*M7,1+0.41*M7) -> 1.6765 | J7: =IF(Ввод!$D$1=1,2+1.74*M7,1.8+1.33*M7) -> 3.9945 | K7: =(1/SQRT(2))*SQRT(J7^2-I7^2/2) -> 2.6972861 | L7: =0.84*J7 -> 3.35538 | M7: =IF(OR(ISBLANK(F6),ISBLANK(F8)),"",ABS(F8-F6)/(A8-A6)) -> 1.65 | N7: =IF(OR(ISBLANK(B7),ISBLANK(C7)),"НЕ РАССЧИТАНО",IF(AND(ISNUMBER(H7),ISNUMBER(I7)),IF(H7<=I7,"OK","НЕ СООТВЕТСТВУЕТ"),"НЕ РАССЧИТАНО")) -> OK | O7: =IF(ISNUMBER(A7),IF(Ввод!$D$1=1,ROUND(A7+G7,1),A7),"") -> 25
A8: 30 | B8: =Ввод!C10 -> 244 | C8: =Ввод!D10 -> 244 | D8: =IF(OR(ISBLANK(B8),ISBLANK(C8)),B8,MROUND((B8+C8)/2,0.5)) -> 244 | E8: =0.00012*(760-Ввод!$B$1)*(273+D8) -> 0.3102 | F8: =IF(ISBLANK(D8),"",MROUND(D8+E8,0.5)) -> 244.5 | G8: =IF(Ввод!$B$1>760,Ввод!E25,0.5+(Ввод!E25-0.5)/(1+(760-Ввод!$B$1)/60)) -> 0.5 | H8: =IF(OR(ISBLANK(B8),ISBLANK(C8)),"",ABS(B8-C8)) -> 0 | I8: =IF(Ввод!$D$1=1,1.2+0.86*M8,1+0.41*M8) -> 1.615 | J8: =IF(Ввод!$D$1=1,2+1.74*M8,1.8+1.33*M8) -> 3.795 | K8: =(1/SQRT(2))*SQRT(J8^2-I8^2/2) -> 2.5590929 | L8: =0.84*J8 -> 3.1878 | M8: =IF(OR(ISBLANK(F7),ISBLANK(F9)),"",ABS(F9-F7)/(A9-A7)) -> 1.5 | N8: =IF(OR(ISBLANK(B8),ISBLANK(C8)),"НЕ РАССЧИТАНО",IF(AND(ISNUMBER(H8),ISNUMBER(I8)),IF(H8<=I8,"OK","НЕ СООТВЕТСТВУЕТ"),"НЕ РАССЧИТАНО")) -> OK | O8: =IF(ISNUMBER(A8),IF(Ввод!$D$1=1,ROUND(A8+G8,1),A8),"") -> 30
A9: 35 | B9: =Ввод!C11 -> 250 | C9: =Ввод!D11 -> 250 | D9: =IF(OR(ISBLANK(B9),ISBLANK(C9)),B9,MROUND((B9+C9)/2,0.5)) -> 250 | E9: =0.00012*(760-Ввод!$B$1)*(273+D9) -> 0.3138 | F9: =IF(ISBLANK(D9),"",MROUND(D9+E9,0.5)) -> 250.5 | G9: =IF(Ввод!$B$1>760,Ввод!E25,0.5+(Ввод!E25-0.5)/(1+(760-Ввод!$B$1)/60)) -> 0.5 | H9: =IF(OR(ISBLANK(B9),ISBLANK(C9)),"",ABS(B9-C9)) -> 0 | I9: =IF(Ввод!$D$1=1,1.2+0.86*M9,1+0.41*M9) -> 1.5125 | J9: =IF(Ввод!$D$1=1,2+1.74*M9,1.8+1.33*M9) -> 3.4625 | K9: =(1/SQRT(2))*SQRT(J9^2-I9^2/2) -> 2.3286346 | L9: =0.84*J9 -> 2.9085 | M9: =IF(OR(ISBLANK(F8),ISBLANK(F10)),"",ABS(F10-F8)/(A10-A8)) -> 1.25 | N9: =IF(OR(ISBLANK(B9),ISBLANK(C9)),"НЕ РАССЧИТАНО",IF(AND(ISNUMBER(H9),ISNUMBER(I9)),IF(H9<=I9,"OK","НЕ СООТВЕТСТВУЕТ"),"НЕ РАССЧИТАНО")) -> OK | O9: =IF(ISNUMBER(A9),IF(Ввод!$D$1=1,ROUND(A9+G9,1),A9),"") -> 35
A10: 40 | B10: =Ввод!C12 -> 256.5 | C10: =Ввод!D12 -> 256.5 | D10: =IF(OR(ISBLANK(B10),ISBLANK(C10)),B10,MROUND((B10+C10)/2,0.5)) -> 256.5 | E10: =0.00012*(760-Ввод!$B$1)*(273+D10) -> 0.3177 | F10: =IF(ISBLANK(D10),"",MROUND(D10+E10,0.5)) -> 257 | G10: =IF(Ввод!$B$1>760,Ввод!E25,0.5+(Ввод!E25-0.5)/(1+(760-Ввод!$B$1)/60)) -> 0.5 | H10: =IF(OR(ISBLANK(B10),ISBLANK(C10)),"",ABS(B10-C10)) -> 0 | I10: =IF(Ввод!$D$1=1,1.2+0.86*M10,1+0.41*M10) -> 1.492 | J10: =IF(Ввод!$D$1=1,2+1.74*M10,1.8+1.33*M10) -> 3.396 | K10: =(1/SQRT(2))*SQRT(J10^2-I10^2/2) -> 2.2825188 | L10: =0.84*J10 -> 2.85264 | M10: =IF(OR(ISBLANK(F9),ISBLANK(F11)),"",ABS(F11-F9)/(A11-A9)) -> 1.2 | N10: =IF(OR(ISBLANK(B10),ISBLANK(C10)),"НЕ РАССЧИТАНО",IF(AND(ISNUMBER(H10),ISNUMBER(I10)),IF(H10<=I10,"OK","НЕ СООТВЕТСТВУЕТ"),"НЕ РАССЧИТАНО")) -> OK | O10: =IF(ISNUMBER(A10),IF(Ввод!$D$1=1,ROUND(A10+G10,1),A10),"") -> 40
A11: 45 | B11: =Ввод!C13 -> 262 | C11: =Ввод!D13 -> 262 | D11: =IF(OR(ISBLANK(B11),ISBLANK(C11)),B11,MROUND((B11+C11)/2,0.5)) -> 262 | E11: =0.00012*(760-Ввод!$B$1)*(273+D11) -> 0.321 | F11: =IF(ISBLANK(D11),"",MROUND(D11+E11,0.5)) -> 262.5 | G11: =IF(Ввод!$B$1>760,Ввод!E25,0.5+(Ввод!E25-0.5)/(1+(760-Ввод!$B$1)/60)) -> 0.5 | H11: =IF(OR(ISBLANK(B11),ISBLANK(C11)),"",ABS(B11-C11)) -> 0 | I11: =IF(Ввод!$D$1=1,1.2+0.86*M11,1+0.41*M11) -> 1.5125 | J11: =IF(Ввод!$D$1=1,2+1.74*M11,1.8+1.33*M11) -> 3.4625 | K11: =(1/SQRT(2))*SQRT(J11^2-I11^2/2) -> 2.3286346 | L11: =0.84*J11 -> 2.9085 | M11: =IF(OR(ISBLANK(F10),ISBLANK(F12)),"",ABS(F12-F10)/(A12-A10)) -> 1.25 | N11: =IF(OR(ISBLANK(B11),ISBLANK(C11)),"НЕ РАССЧИТАНО",IF(AND(ISNUMBER(H11),ISNUMBER(I11)),IF(H11<=I11,"OK","НЕ СООТВЕТСТВУЕТ"),"НЕ РАССЧИТАНО")) -> OK | O11: =IF(ISNUMBER(A11),IF(Ввод!$D$1=1,ROUND(A11+G11,1),A11),"") -> 45
A12: 50 | B12: =Ввод!C14 -> 268.75 | C12: =Ввод!D14 -> 268.75 | D12: =IF(OR(ISBLANK(B12),ISBLANK(C12)),B12,MROUND((B12+C12)/2,0.5)) -> 269 | E12: =0.00012*(760-Ввод!$B$1)*(273+D12) -> 0.3252 | F12: =IF(ISBLANK(D12),"",MROUND(D12+E12,0.5)) -> 269.5 | G12: =IF(Ввод!$B$1>760,Ввод!E25,0.5+(Ввод!E25-0.5)/(1+(760-Ввод!$B$1)/60)) -> 0.5 | H12: =IF(OR(ISBLANK(B12),ISBLANK(C12)),"",ABS(B12-C12)) -> 0 | I12: =IF(Ввод!$D$1=1,1.2+0.86*M12,1+0.41*M12) -> 1.492 | J12: =IF(Ввод!$D$1=1,2+1.74*M12,1.8+1.33*M12) -> 3.396 | K12: =(1/SQRT(2))*SQRT(J12^2-I12^2/2) -> 2.2825188 | L12: =0.84*J12 -> 2.85264 | M12: =IF(OR(ISBLANK(F11),ISBLANK(F13)),"",ABS(F13-F11)/(A13-A11)) -> 1.2 | N12: =IF(OR(ISBLANK(B12),ISBLANK(C12)),"НЕ РАССЧИТАНО",IF(AND(ISNUMBER(H12),ISNUMBER(I12)),IF(H12<=I12,"OK","НЕ СООТВЕТСТВУЕТ"),"НЕ РАССЧИТАНО")) -> OK | O12: =IF(ISNUMBER(A12),IF(Ввод!$D$1=1,ROUND(A12+G12,1),A12),"") -> 50
A13: 55 | B13: =Ввод!C15 -> 274 | C13: =Ввод!D15 -> 274 | D13: =IF(OR(ISBLANK(B13),ISBLANK(C13)),B13,MROUND((B13+C13)/2,0.5)) -> 274 | E13: =0.00012*(760-Ввод!$B$1)*(273+D13) -> 0.3282 | F13: =IF(ISBLANK(D13),"",MROUND(D13+E13,0.5)) -> 274.5 | G13: =IF(Ввод!$B$1>760,Ввод!E25,0.5+(Ввод!E25-0.5)/(1+(760-Ввод!$B$1)/60)) -> 0.5 | H13: =IF(OR(ISBLANK(B13),ISBLANK(C13)),"",ABS(B13-C13)) -> 0 | I13: =IF(Ввод!$D$1=1,1.2+0.86*M13,1+0.41*M13) -> 1.4715 | J13: =IF(Ввод!$D$1=1,2+1.74*M13,1.8+1.33*M13) -> 3.3295 | K13: =(1/SQRT(2))*SQRT(J13^2-I13^2/2) -> 2.2363938 | L13: =0.84*J13 -> 2.79678 | M13: =IF(OR(ISBLANK(F12),ISBLANK(F14)),"",ABS(F14-F12)/(A14-A12)) -> 1.15 | N13: =IF(OR(ISBLANK(B13),ISBLANK(C13)),"НЕ РАССЧИТАНО",IF(AND(ISNUMBER(H13),ISNUMBER(I13)),IF(H13<=I13,"OK","НЕ СООТВЕТСТВУЕТ"),"НЕ РАССЧИТАНО")) -> OK | O13: =IF(ISNUMBER(A13),IF(Ввод!$D$1=1,ROUND(A13+G13,1),A13),"") -> 55
A14: 60 | B14: =Ввод!C16 -> 280.5 | C14: =Ввод!D16 -> 280.5 | D14: =IF(OR(ISBLANK(B14),ISBLANK(C14)),B14,MROUND((B14+C14)/2,0.5)) -> 280.5 | E14: =0.00012*(760-Ввод!$B$1)*(273+D14) -> 0.3321 | F14: =IF(ISBLANK(D14),"",MROUND(D14+E14,0.5)) -> 281 | G14: =IF(Ввод!$B$1>760,Ввод!E25,0.5+(Ввод!E25-0.5)/(1+(760-Ввод!$B$1)/60)) -> 0.5 | H14: =IF(OR(ISBLANK(B14),ISBLANK(C14)),"",ABS(B14-C14)) -> 0 | I14: =IF(Ввод!$D$1=1,1.2+0.86*M14,1+0.41*M14) -> 1.533 | J14: =IF(Ввод!$D$1=1,2+1.74*M14,1.8+1.33*M14) -> 3.529 | K14: =(1/SQRT(2))*SQRT(J14^2-I14^2/2) -> 2.3747417 | L14: =0.84*J14 -> 2.96436 | M14: =IF(OR(ISBLANK(F13),ISBLANK(F15)),"",ABS(F15-F13)/(A15-A13)) -> 1.3 | N14: =IF(OR(ISBLANK(B14),ISBLANK(C14)),"НЕ РАССЧИТАНО",IF(AND(ISNUMBER(H14),ISNUMBER(I14)),IF(H14<=I14,"OK","НЕ СООТВЕТСТВУЕТ"),"НЕ РАССЧИТАНО")) -> OK | O14: =IF(ISNUMBER(A14),IF(Ввод!$D$1=1,ROUND(A14+G14,1),A14),"") -> 60
A15: 65 | B15: =Ввод!C17 -> 287 | C15: =Ввод!D17 -> 287 | D15: =IF(OR(ISBLANK(B15),ISBLANK(C15)),B15,MROUND((B15+C15)/2,0.5)) -> 287 | E15: =0.00012*(760-Ввод!$B$1)*(273+D15) -> 0.336 | F15: =IF(ISBLANK(D15),"",MROUND(D15+E15,0.5)) -> 287.5 | G15: =IF(Ввод!$B$1>760,Ввод!E25,0.5+(Ввод!E25-0.5)/(1+(760-Ввод!$B$1)/60)) -> 0.5 | H15: =IF(OR(ISBLANK(B15),ISBLANK(C15)),"",ABS(B15-C15)) -> 0 | I15: =IF(Ввод!$D$1=1,1.2+0.86*M15,1+0.41*M15) -> 1.5535 | J15: =IF(Ввод!$D$1=1,2+1.74*M15,1.8+1.33*M15) -> 3.5955 | K15: =(1/SQRT(2))*SQRT(J15^2-I15^2/2) -> 2.4208407 | L15: =0.84*J15 -> 3.02022 | M15: =IF(OR(ISBLANK(F14),ISBLANK(F16)),"",ABS(F16-F14)/(A16-A14)) -> 1.35 | N15: =IF(OR(ISBLANK(B15),ISBLANK(C15)),"НЕ РАССЧИТАНО",IF(AND(ISNUMBER(H15),ISNUMBER(I15)),IF(H15<=I15,"OK","НЕ СООТВЕТСТВУЕТ"),"НЕ РАССЧИТАНО")) -> OK | O15: =IF(ISNUMBER(A15),IF(Ввод!$D$1=1,ROUND(A15+G15,1),A15),"") -> 65
A16: 70 | B16: =Ввод!C18 -> 293.75 | C16: =Ввод!D18 -> 293.75 | D16: =IF(OR(ISBLANK(B16),ISBLANK(C16)),B16,MROUND((B16+C16)/2,0.5)) -> 294 | E16: =0.00012*(760-Ввод!$B$1)*(273+D16) -> 0.3402 | F16: =IF(ISBLANK(D16),"",MROUND(D16+E16,0.5)) -> 294.5 | G16: =IF(Ввод!$B$1>760,Ввод!E25,0.5+(Ввод!E25-0.5)/(1+(760-Ввод!$B$1)/60)) -> 0.5 | H16: =IF(OR(ISBLANK(B16),ISBLANK(C16)),"",ABS(B16-C16)) -> 0 | I16: =IF(Ввод!$D$1=1,1.2+0.86*M16,1+0.41*M16) -> 1.533 | J16: =IF(Ввод!$D$1=1,2+1.74*M16,1.8+1.33*M16) -> 3.529 | K16: =(1/SQRT(2))*SQRT(J16^2-I16^2/2) -> 2.3747417 | L16: =0.84*J16 -> 2.96436 | M16: =IF(OR(ISBLANK(F15),ISBLANK(F17)),"",ABS(F17-F15)/(A17-A15)) -> 1.3 | N16: =IF(OR(ISBLANK(B16),ISBLANK(C16)),"НЕ РАССЧИТАНО",IF(AND(ISNUMBER(H16),ISNUMBER(I16)),IF(H16<=I16,"OK","НЕ СООТВЕТСТВУЕТ"),"НЕ РАССЧИТАНО")) -> OK | O16: =IF(ISNUMBER(A16),IF(Ввод!$D$1=1,ROUND(A16+G16,1),A16),"") -> 70
A17: 75 | B17: =Ввод!C19 -> 300 | C17: =Ввод!D19 -> 300 | D17: =IF(OR(ISBLANK(B17),ISBLANK(C17)),B17,MROUND((B17+C17)/2,0.5)) -> 300 | E17: =0.00012*(760-Ввод!$B$1)*(273+D17) -> 0.3438 | F17: =IF(ISBLANK(D17),"",MROUND(D17+E17,0.5)) -> 300.5 | G17: =IF(Ввод!$B$1>760,Ввод!E25,0.5+(Ввод!E25-0.5)/(1+(760-Ввод!$B$1)/60)) -> 0.5 | H17: =IF(OR(ISBLANK(B17),ISBLANK(C17)),"",ABS(B17-C17)) -> 0 | I17: =IF(Ввод!$D$1=1,1.2+0.86*M17,1+0.41*M17) -> 1.6355 | J17: =IF(Ввод!$D$1=1,2+1.74*M17,1.8+1.33*M17) -> 3.8615 | K17: =(1/SQRT(2))*SQRT(J17^2-I17^2/2) -> 2.6051633 | L17: =0.84*J17 -> 3.24366 | M17: =IF(OR(ISBLANK(F16),ISBLANK(F18)),"",ABS(F18-F16)/(A18-A16)) -> 1.55 | N17: =IF(OR(ISBLANK(B17),ISBLANK(C17)),"НЕ РАССЧИТАНО",IF(AND(ISNUMBER(H17),ISNUMBER(I17)),IF(H17<=I17,"OK","НЕ СООТВЕТСТВУЕТ"),"НЕ РАССЧИТАНО")) -> OK | O17: =IF(ISNUMBER(A17),IF(Ввод!$D$1=1,ROUND(A17+G17,1),A17),"") -> 75
A18: 80 | B18: =Ввод!C20 -> 309.25 | C18: =Ввод!D20 -> 309.25 | D18: =IF(OR(ISBLANK(B18),ISBLANK(C18)),B18,MROUND((B18+C18)/2,0.5)) -> 309.5 | E18: =0.00012*(760-Ввод!$B$1)*(273+D18) -> 0.3495 | F18: =IF(ISBLANK(D18),"",MROUND(D18+E18,0.5)) -> 310 | G18: =IF(Ввод!$B$1>760,Ввод!E25,0.5+(Ввод!E25-0.5)/(1+(760-Ввод!$B$1)/60)) -> 0.5 | H18: =IF(OR(ISBLANK(B18),ISBLANK(C18)),"",ABS(B18-C18)) -> 0 | I18: =IF(Ввод!$D$1=1,1.2+0.86*M18,1+0.41*M18) -> 1.738 | J18: =IF(Ввод!$D$1=1,2+1.74*M18,1.8+1.33*M18) -> 4.194 | K18: =(1/SQRT(2))*SQRT(J18^2-I18^2/2) -> 2.8354289 | L18: =0.84*J18 -> 3.52296 | M18: =IF(OR(ISBLANK(F17),ISBLANK(F19)),"",ABS(F19-F17)/(A19-A17)) -> 1.8 | N18: =IF(OR(ISBLANK(B18),ISBLANK(C18)),"НЕ РАССЧИТАНО",IF(AND(ISNUMBER(H18),ISNUMBER(I18)),IF(H18<=I18,"OK","НЕ СООТВЕТСТВУЕТ"),"НЕ РАССЧИТАНО")) -> OK | O18: =IF(ISNUMBER(A18),IF(Ввод!$D$1=1,ROUND(A18+G18,1),A18),"") -> 80
A19: 85 | B19: =Ввод!C21 -> 318 | C19: =Ввод!D21 -> 318 | D19: =IF(OR(ISBLANK(B19),ISBLANK(C19)),B19,MROUND((B19+C19)/2,0.5)) -> 318 | E19: =0.00012*(760-Ввод!$B$1)*(273+D19) -> 0.3546 | F19: =IF(ISBLANK(D19),"",MROUND(D19+E19,0.5)) -> 318.5 | G19: =IF(Ввод!$B$1>760,Ввод!E25,0.5+(Ввод!E25-0.5)/(1+(760-Ввод!$B$1)/60)) -> 0.5 | H19: =IF(OR(ISBLANK(B19),ISBLANK(C19)),"",ABS(B19-C19)) -> 0 | I19: =IF(Ввод!$D$1=1,1.2+0.86*M19,1+0.41*M19) -> 1.8405 | J19: =IF(Ввод!$D$1=1,2+1.74*M19,1.8+1.33*M19) -> 4.5265 | K19: =(1/SQRT(2))*SQRT(J19^2-I19^2/2) -> 3.0655735 | L19: =0.84*J19 -> 3.80226 | M19: =IF(OR(ISBLANK(F18),ISBLANK(F20)),"",ABS(F20-F18)/(A20-A18)) -> 2.05 | N19: =IF(OR(ISBLANK(B19),ISBLANK(C19)),"НЕ РАССЧИТАНО",IF(AND(ISNUMBER(H19),ISNUMBER(I19)),IF(H19<=I19,"OK","НЕ СООТВЕТСТВУЕТ"),"НЕ РАССЧИТАНО")) -> OK | O19: =IF(ISNUMBER(A19),IF(Ввод!$D$1=1,ROUND(A19+G19,1),A19),"") -> 85
A20: 90 | B20: =Ввод!C22 -> 329.75 | C20: =Ввод!D22 -> 329.75 | D20: =IF(OR(ISBLANK(B20),ISBLANK(C20)),B20,MROUND((B20+C20)/2,0.5)) -> 330 | E20: =0.00012*(760-Ввод!$B$1)*(273+D20) -> 0.3618 | F20: =IF(ISBLANK(D20),"",MROUND(D20+E20,0.5)) -> 330.5 | G20: =IF(Ввод!$B$1>760,Ввод!E25,0.5+(Ввод!E25-0.5)/(1+(760-Ввод!$B$1)/60)) -> 0.5 | H20: =IF(OR(ISBLANK(B20),ISBLANK(C20)),"",ABS(B20-C20)) -> 0 | I20: =IF(Ввод!$D$1=1,1.2+0.86*M20,1+0.41*M20) -> 2.1275 | J20: =IF(Ввод!$D$1=1,0.8+1.74*M20,1.8+1.33*M20) -> 5.4575 | K20: =(1/SQRT(2))*SQRT(J20^2-I20^2/2) -> 3.7095268 | L20: =0.84*J20 -> 4.5843 | M20: =IF(OR(ISBLANK(F19),ISBLANK(F21)),"",ABS(F21-F19)/(A21-A19)) -> 2.75 | N20: =IF(OR(ISBLANK(B20),ISBLANK(C20)),"НЕ РАССЧИТАНО",IF(AND(ISNUMBER(H20),ISNUMBER(I20)),IF(H20<=I20,"OK","НЕ СООТВЕТСТВУЕТ"),"НЕ РАССЧИТАНО")) -> OK | O20: =IF(ISNUMBER(A20),IF(Ввод!$D$1=1,ROUND(A20+G20,1),A20),"") -> 90
A21: 95 | B21: =Ввод!C23 -> 345.25 | C21: =Ввод!D23 -> 345.25 | D21: =IF(OR(ISBLANK(B21),ISBLANK(C21)),B21,MROUND((B21+C21)/2,0.5)) -> 345.5 | E21: =0.00012*(760-Ввод!$B$1)*(273+D21) -> 0.3711 | F21: =IF(ISBLANK(D21),"",MROUND(D21+E21,0.5)) -> 346 | G21: =IF(Ввод!$B$1>760,Ввод!E25,0.5+(Ввод!E25-0.5)/(1+(760-Ввод!$B$1)/60)) -> 0.5 | H21: =IF(OR(ISBLANK(B21),ISBLANK(C21)),"",ABS(B21-C21)) -> 0 | I21: =IF(Ввод!$D$1=1,1.2+0.86*M21,1+0.41*M21) -> 2.271 | J21: =IF(Ввод!$D$1=1,1.1+1.74*M21,1.8+1.33*M21) -> 5.923 | K21: =(1/SQRT(2))*SQRT(J21^2-I21^2/2) -> 4.0313279 | L21: =0.84*J21 -> 4.97532 | M21: =IF(OR(ISBLANK(F20),ISBLANK(F21)),"",ABS(F21-F20)/(A21-A20)) -> 3.1 | N21: =IF(OR(ISBLANK(B21),ISBLANK(C21)),"НЕ РАССЧИТАНО",IF(AND(ISNUMBER(H21),ISNUMBER(I21)),IF(H21<=I21,"OK","НЕ СООТВЕТСТВУЕТ"),"НЕ РАССЧИТАНО")) -> OK | O21: =IF(ISNUMBER(A21),IF(Ввод!$D$1=1,ROUND(A21+G21,1),A21),"") -> 95
A22: 100 | B22: =Ввод!C24 -> 355 | C22: =Ввод!D24 -> 355 | D22: =IF(OR(ISBLANK(B22),ISBLANK(C22)),B22,MROUND((B22+C22)/2,0.5)) -> 355 | E22: =0.00012*(760-Ввод!$B$1)*(273+D22) -> 0.3768 | F22: =IF(ISBLANK(D22),"",MROUND(D22+E22,0.5)) -> 355.5 | G22: =IF(Ввод!$B$1>760,Ввод!E25,0.5+(Ввод!E25-0.5)/(1+(760-Ввод!$B$1)/60)) -> 0.5 | H22: =IF(OR(ISBLANK(B22),ISBLANK(C22)),"",ABS(B22-C22)) -> 0 | I22: =IF(Ввод!$D$1=1,3.9,0.36*M22+0.7) -> 1.384 | J22: =IF(Ввод!$D$1=1,7.2,0.42*M22+3.1) -> 3.898 | K22: =(1/SQRT(2))*SQRT(J22^2-I22^2/2) -> 2.6680214 | L22: =0.84*J22 -> 3.27432 | M22: =IF(OR(ISBLANK(F21),ISBLANK(F22)),"",ABS(F22-F21)/5) -> 1.9 | N22: =IF(OR(ISBLANK(B22),ISBLANK(C22)),"НЕ РАССЧИТАНО",IF(AND(ISNUMBER(H22),ISNUMBER(I22)),IF(H22<=I22,"OK","НЕ СООТВЕТСТВУЕТ"),"НЕ РАССЧИТАНО")) -> OK | O22: =IF(ISNUMBER(A22),IF(Ввод!$D$1=1,ROUND(A22+G22,1),A22),"") -> 100
A25: ВЕТКА 2 — ЗАДАНЫ ТЕМПЕРАТУРЫ (независимая ветка, ввод на этом листе): температуры из НД (нормируемые при 760 мм рт.ст.) → T_фикс (что ФИКСИРОВАТЬ на термометре при текущем давлении) → лаборант вводит ОБЪЁМЫ двух параллелей (V1, V2) → Vср, % = (V1+V2)/2 / Ввод!$G$1 * 100 → второй график и вторая модель
A26: T_НД (при 760), °C | B26: T_фикс (ФИКСИРОВАТЬ), °C | C26: C_проверка, °C | D26: V1, мл (проба 1) | E26: V2, мл (проба 2) | F26: Vср, % | G26: r, % | H26: Статус | I26: ПОДСКАЗКА
A27: 150 | B27: =IF(ISNUMBER(A27),(A27-0.00012*(760-Ввод!$B$1)*273)/(1+0.00012*(760-Ввод!$B$1)),"") -> 149.74635 | C27: =IF(ISNUMBER(A27),B27+0.00012*(760-Ввод!$B$1)*(273+B27)-A27,"") -> 0 | D27: 5 | E27: 4 | F27: =IF(AND(ISNUMBER(D27),ISNUMBER(E27)),(D27+E27)/2/Ввод!$G$1*100,"") -> 4.5 | G27: =IF(AND(ISNUMBER(D27),ISNUMBER(E27),F27<>0),ABS(D27-E27)/(D27+E27)*100,"") -> 11.111111 | H27: =IF(ISNUMBER(A27),IF(AND(ISNUMBER(D27),ISNUMBER(E27)),"OK","введи V1 и V2"),"—") -> OK | I27: ВЕТКА 2 — НЕЗАВИСИМАЯ ветка «заданы температуры». 1) В колонку A (T_НД) введите числами температуры из НД (нормируемые при 760), например 150, 160, 250. 2) В колонке B — T_фикс = (T_цель − k·273)/(1+k): какую температуру ФИКСИРОВАТЬ на термометре при текущем давлении; C_проверка≈0 — пересчёт верен. 3) Проведите дистилляцию, фиксируя T_фикс, и вбейте объёмы ДВУХ ПАРАЛЛЕЛЕЙ: колонки D (V1, мл, проба 1) и E (V2, мл, проба 2) — зелёные. 4) Vср, % = (V1+V2)/2 / Ввод!$G$1 * 100 — расчёт (F). По точкам (Vср → T_НД) строится ВТОРОЙ график и ВТОРАЯ модель (кубический полином) — см. лист «График». Ветка 1 и Ветка 2 НЕЗАВИСИМЫ.
A28: 200 | B28: =IF(ISNUMBER(A28),(A28-0.00012*(760-Ввод!$B$1)*273)/(1+0.00012*(760-Ввод!$B$1)),"") -> 199.71637 | C28: =IF(ISNUMBER(A28),B28+0.00012*(760-Ввод!$B$1)*(273+B28)-A28,"") -> 2.8421709e-14 | D28: 7 | E28: 6 | F28: =IF(AND(ISNUMBER(D28),ISNUMBER(E28)),(D28+E28)/2/Ввод!$G$1*100,"") -> 6.5 | G28: =IF(AND(ISNUMBER(D28),ISNUMBER(E28),F28<>0),ABS(D28-E28)/(D28+E28)*100,"") -> 7.6923077 | H28: =IF(ISNUMBER(A28),IF(AND(ISNUMBER(D28),ISNUMBER(E28)),"OK","введи V1 и V2"),"—") -> OK
A29: 250 | B29: =IF(ISNUMBER(A29),(A29-0.00012*(760-Ввод!$B$1)*273)/(1+0.00012*(760-Ввод!$B$1)),"") -> 249.68639 | C29: =IF(ISNUMBER(A29),B29+0.00012*(760-Ввод!$B$1)*(273+B29)-A29,"") -> 0 | D29: 10 | E29: 9 | F29: =IF(AND(ISNUMBER(D29),ISNUMBER(E29)),(D29+E29)/2/Ввод!$G$1*100,"") -> 9.5 | G29: =IF(AND(ISNUMBER(D29),ISNUMBER(E29),F29<>0),ABS(D29-E29)/(D29+E29)*100,"") -> 5.2631579 | H29: =IF(ISNUMBER(A29),IF(AND(ISNUMBER(D29),ISNUMBER(E29)),"OK","введи V1 и V2"),"—") -> OK
A30: 300 | B30: =IF(ISNUMBER(A30),(A30-0.00012*(760-Ввод!$B$1)*273)/(1+0.00012*(760-Ввод!$B$1)),"") -> 299.65641 | C30: =IF(ISNUMBER(A30),B30+0.00012*(760-Ввод!$B$1)*(273+B30)-A30,"") -> 5.6843419e-14 | D30: 14 | E30: 13 | F30: =IF(AND(ISNUMBER(D30),ISNUMBER(E30)),(D30+E30)/2/Ввод!$G$1*100,"") -> 13.5 | G30: =IF(AND(ISNUMBER(D30),ISNUMBER(E30),F30<>0),ABS(D30-E30)/(D30+E30)*100,"") -> 3.7037037 | H30: =IF(ISNUMBER(A30),IF(AND(ISNUMBER(D30),ISNUMBER(E30)),"OK","введи V1 и V2"),"—") -> OK
A31: 350 | B31: =IF(ISNUMBER(A31),(A31-0.00012*(760-Ввод!$B$1)*273)/(1+0.00012*(760-Ввод!$B$1)),"") -> 349.62642 | C31: =IF(ISNUMBER(A31),B31+0.00012*(760-Ввод!$B$1)*(273+B31)-A31,"") -> 0 | D31: 17 | E31: 18 | F31: =IF(AND(ISNUMBER(D31),ISNUMBER(E31)),(D31+E31)/2/Ввод!$G$1*100,"") -> 17.5 | G31: =IF(AND(ISNUMBER(D31),ISNUMBER(E31),F31<>0),ABS(D31-E31)/(D31+E31)*100,"") -> 2.8571429 | H31: =IF(ISNUMBER(A31),IF(AND(ISNUMBER(D31),ISNUMBER(E31)),"OK","введи V1 и V2"),"—") -> OK
B32: =IF(ISNUMBER(A32),(A32-0.00012*(760-Ввод!$B$1)*273)/(1+0.00012*(760-Ввод!$B$1)),"") | C32: =IF(ISNUMBER(A32),B32+0.00012*(760-Ввод!$B$1)*(273+B32)-A32,"") | F32: =IF(AND(ISNUMBER(D32),ISNUMBER(E32)),(D32+E32)/2/Ввод!$G$1*100,"") | G32: =IF(AND(ISNUMBER(D32),ISNUMBER(E32),F32<>0),ABS(D32-E32)/(D32+E32)*100,"") | H32: =IF(ISNUMBER(A32),IF(AND(ISNUMBER(D32),ISNUMBER(E32)),"OK","введи V1 и V2"),"—") -> —
B33: =IF(ISNUMBER(A33),(A33-0.00012*(760-Ввод!$B$1)*273)/(1+0.00012*(760-Ввод!$B$1)),"") | C33: =IF(ISNUMBER(A33),B33+0.00012*(760-Ввод!$B$1)*(273+B33)-A33,"") | F33: =IF(AND(ISNUMBER(D33),ISNUMBER(E33)),(D33+E33)/2/Ввод!$G$1*100,"") | G33: =IF(AND(ISNUMBER(D33),ISNUMBER(E33),F33<>0),ABS(D33-E33)/(D33+E33)*100,"") | H33: =IF(ISNUMBER(A33),IF(AND(ISNUMBER(D33),ISNUMBER(E33)),"OK","введи V1 и V2"),"—") -> —
B34: =IF(ISNUMBER(A34),(A34-0.00012*(760-Ввод!$B$1)*273)/(1+0.00012*(760-Ввод!$B$1)),"") | C34: =IF(ISNUMBER(A34),B34+0.00012*(760-Ввод!$B$1)*(273+B34)-A34,"") | F34: =IF(AND(ISNUMBER(D34),ISNUMBER(E34)),(D34+E34)/2/Ввод!$G$1*100,"") | G34: =IF(AND(ISNUMBER(D34),ISNUMBER(E34),F34<>0),ABS(D34-E34)/(D34+E34)*100,"") | H34: =IF(ISNUMBER(A34),IF(AND(ISNUMBER(D34),ISNUMBER(E34)),"OK","введи V1 и V2"),"—") -> —
B35: =IF(ISNUMBER(A35),(A35-0.00012*(760-Ввод!$B$1)*273)/(1+0.00012*(760-Ввод!$B$1)),"") | C35: =IF(ISNUMBER(A35),B35+0.00012*(760-Ввод!$B$1)*(273+B35)-A35,"") | F35: =IF(AND(ISNUMBER(D35),ISNUMBER(E35)),(D35+E35)/2/Ввод!$G$1*100,"") | G35: =IF(AND(ISNUMBER(D35),ISNUMBER(E35),F35<>0),ABS(D35-E35)/(D35+E35)*100,"") | H35: =IF(ISNUMBER(A35),IF(AND(ISNUMBER(D35),ISNUMBER(E35)),"OK","введи V1 и V2"),"—") -> —
B36: =IF(ISNUMBER(A36),(A36-0.00012*(760-Ввод!$B$1)*273)/(1+0.00012*(760-Ввод!$B$1)),"") | C36: =IF(ISNUMBER(A36),B36+0.00012*(760-Ввод!$B$1)*(273+B36)-A36,"") | F36: =IF(AND(ISNUMBER(D36),ISNUMBER(E36)),(D36+E36)/2/Ввод!$G$1*100,"") | G36: =IF(AND(ISNUMBER(D36),ISNUMBER(E36),F36<>0),ABS(D36-E36)/(D36+E36)*100,"") | H36: =IF(ISNUMBER(A36),IF(AND(ISNUMBER(D36),ISNUMBER(E36)),"OK","введи V1 и V2"),"—") -> —
B37: =IF(ISNUMBER(A37),(A37-0.00012*(760-Ввод!$B$1)*273)/(1+0.00012*(760-Ввод!$B$1)),"") | C37: =IF(ISNUMBER(A37),B37+0.00012*(760-Ввод!$B$1)*(273+B37)-A37,"") | F37: =IF(AND(ISNUMBER(D37),ISNUMBER(E37)),(D37+E37)/2/Ввод!$G$1*100,"") | G37: =IF(AND(ISNUMBER(D37),ISNUMBER(E37),F37<>0),ABS(D37-E37)/(D37+E37)*100,"") | H37: =IF(ISNUMBER(A37),IF(AND(ISNUMBER(D37),ISNUMBER(E37)),"OK","введи V1 и V2"),"—") -> —
B38: =IF(ISNUMBER(A38),(A38-0.00012*(760-Ввод!$B$1)*273)/(1+0.00012*(760-Ввод!$B$1)),"") | C38: =IF(ISNUMBER(A38),B38+0.00012*(760-Ввод!$B$1)*(273+B38)-A38,"") | F38: =IF(AND(ISNUMBER(D38),ISNUMBER(E38)),(D38+E38)/2/Ввод!$G$1*100,"") | G38: =IF(AND(ISNUMBER(D38),ISNUMBER(E38),F38<>0),ABS(D38-E38)/(D38+E38)*100,"") | H38: =IF(ISNUMBER(A38),IF(AND(ISNUMBER(D38),ISNUMBER(E38)),"OK","введи V1 и V2"),"—") -> —
B39: =IF(ISNUMBER(A39),(A39-0.00012*(760-Ввод!$B$1)*273)/(1+0.00012*(760-Ввод!$B$1)),"") | C39: =IF(ISNUMBER(A39),B39+0.00012*(760-Ввод!$B$1)*(273+B39)-A39,"") | F39: =IF(AND(ISNUMBER(D39),ISNUMBER(E39)),(D39+E39)/2/Ввод!$G$1*100,"") | G39: =IF(AND(ISNUMBER(D39),ISNUMBER(E39),F39<>0),ABS(D39-E39)/(D39+E39)*100,"") | H39: =IF(ISNUMBER(A39),IF(AND(ISNUMBER(D39),ISNUMBER(E39)),"OK","введи V1 и V2"),"—") -> —
B40: =IF(ISNUMBER(A40),(A40-0.00012*(760-Ввод!$B$1)*273)/(1+0.00012*(760-Ввод!$B$1)),"") | C40: =IF(ISNUMBER(A40),B40+0.00012*(760-Ввод!$B$1)*(273+B40)-A40,"") | F40: =IF(AND(ISNUMBER(D40),ISNUMBER(E40)),(D40+E40)/2/Ввод!$G$1*100,"") | G40: =IF(AND(ISNUMBER(D40),ISNUMBER(E40),F40<>0),ABS(D40-E40)/(D40+E40)*100,"") | H40: =IF(ISNUMBER(A40),IF(AND(ISNUMBER(D40),ISNUMBER(E40)),"OK","введи V1 и V2"),"—") -> —
B41: =IF(ISNUMBER(A41),(A41-0.00012*(760-Ввод!$B$1)*273)/(1+0.00012*(760-Ввод!$B$1)),"") | C41: =IF(ISNUMBER(A41),B41+0.00012*(760-Ввод!$B$1)*(273+B41)-A41,"") | F41: =IF(AND(ISNUMBER(D41),ISNUMBER(E41)),(D41+E41)/2/Ввод!$G$1*100,"") | G41: =IF(AND(ISNUMBER(D41),ISNUMBER(E41),F41<>0),ABS(D41-E41)/(D41+E41)*100,"") | H41: =IF(ISNUMBER(A41),IF(AND(ISNUMBER(D41),ISNUMBER(E41)),"OK","введи V1 и V2"),"—") -> —
B42: =IF(ISNUMBER(A42),(A42-0.00012*(760-Ввод!$B$1)*273)/(1+0.00012*(760-Ввод!$B$1)),"") | C42: =IF(ISNUMBER(A42),B42+0.00012*(760-Ввод!$B$1)*(273+B42)-A42,"") | F42: =IF(AND(ISNUMBER(D42),ISNUMBER(E42)),(D42+E42)/2/Ввод!$G$1*100,"") | G42: =IF(AND(ISNUMBER(D42),ISNUMBER(E42),F42<>0),ABS(D42-E42)/(D42+E42)*100,"") | H42: =IF(ISNUMBER(A42),IF(AND(ISNUMBER(D42),ISNUMBER(E42)),"OK","введи V1 и V2"),"—") -> —
...

Sheet Итог
A1: ИТОГ расчёта D86
A2: Давление, мм рт.ст. | B2: =Ввод!B1 -> 755
A3: Объём образца, мл | B3: =Ввод!G1 -> 100
A5: % отгона | B5: T1 | C5: T2 | D5: T_corr | E5: r | F5: R | G5: Статус
A6: =Расчёт!A2 -> 0 | B6: =Расчёт!B2 -> 161.75 | C6: =Расчёт!C2 -> 161.75 | D6: =Расчёт!F2 -> 162.5 | E6: =Расчёт!I2 -> 2.995 | F6: =Расчёт!J2 -> 8.101 | G6: =Расчёт!N2 -> OK
A7: =Расчёт!A3 -> 5 | B7: =Расчёт!B3 -> 190.5 | C7: =Расчёт!C3 -> 190.5 | D7: =Расчёт!F3 -> 191 | E7: =Расчёт!I3 -> 2.722 | F7: =Расчёт!J3 -> 7.386 | G7: =Расчёт!N3 -> OK
A8: =Расчёт!A4 -> 10 | B8: =Расчёт!B4 -> 203.75 | C8: =Расчёт!C4 -> 203.75 | D8: =Расчёт!F4 -> 204.5 | E8: =Расчёт!I4 -> 1.7995 | F8: =Расчёт!J4 -> 4.3935 | G8: =Расчёт!N4 -> OK
A9: =Расчёт!A5 -> 15 | B9: =Расчёт!B5 -> 210 | C9: =Расчёт!C5 -> 210 | D9: =Расчёт!F5 -> 210.5 | E9: =Расчёт!I5 -> 1.9635 | F9: =Расчёт!J5 -> 4.9255 | G9: =Расчёт!N5 -> OK
A10: =Расчёт!A6 -> 20 | B10: =Расчёт!B6 -> 227.5 | C10: =Расчёт!C6 -> 227.5 | D10: =Расчёт!F6 -> 228 | E10: =Расчёт!I6 -> 2.025 | F10: =Расчёт!J6 -> 5.125 | G10: =Расчёт!N6 -> OK
A11: =Расчёт!A7 -> 25 | B11: =Расчёт!B7 -> 235 | C11: =Расчёт!C7 -> 235 | D11: =Расчёт!F7 -> 235.5 | E11: =Расчёт!I7 -> 1.6765 | F11: =Расчёт!J7 -> 3.9945 | G11: =Расчёт!N7 -> OK
A12: =Расчёт!A8 -> 30 | B12: =Расчёт!B8 -> 244 | C12: =Расчёт!C8 -> 244 | D12: =Расчёт!F8 -> 244.5 | E12: =Расчёт!I8 -> 1.615 | F12: =Расчёт!J8 -> 3.795 | G12: =Расчёт!N8 -> OK
A13: =Расчёт!A9 -> 35 | B13: =Расчёт!B9 -> 250 | C13: =Расчёт!C9 -> 250 | D13: =Расчёт!F9 -> 250.5 | E13: =Расчёт!I9 -> 1.5125 | F13: =Расчёт!J9 -> 3.4625 | G13: =Расчёт!N9 -> OK
A14: =Расчёт!A10 -> 40 | B14: =Расчёт!B10 -> 256.5 | C14: =Расчёт!C10 -> 256.5 | D14: =Расчёт!F10 -> 257 | E14: =Расчёт!I10 -> 1.492 | F14: =Расчёт!J10 -> 3.396 | G14: =Расчёт!N10 -> OK
A15: =Расчёт!A11 -> 45 | B15: =Расчёт!B11 -> 262 | C15: =Расчёт!C11 -> 262 | D15: =Расчёт!F11 -> 262.5 | E15: =Расчёт!I11 -> 1.5125 | F15: =Расчёт!J11 -> 3.4625 | G15: =Расчёт!N11 -> OK
A16: =Расчёт!A12 -> 50 | B16: =Расчёт!B12 -> 268.75 | C16: =Расчёт!C12 -> 268.75 | D16: =Расчёт!F12 -> 269.5 | E16: =Расчёт!I12 -> 1.492 | F16: =Расчёт!J12 -> 3.396 | G16: =Расчёт!N12 -> OK
A17: =Расчёт!A13 -> 55 | B17: =Расчёт!B13 -> 274 | C17: =Расчёт!C13 -> 274 | D17: =Расчёт!F13 -> 274.5 | E17: =Расчёт!I13 -> 1.4715 | F17: =Расчёт!J13 -> 3.3295 | G17: =Расчёт!N13 -> OK
... A26: =Расчёт!A22 -> 100 | B26: =Расчёт!B22 -> 355 | C26: =Расчёт!C22 -> 355 | D26: =Расчёт!F22 -> 355.5 | E26: =Расчёт!I22 -> 1.384 | F26: =Расчёт!J22 -> 3.898 | G26: =Расчёт!N22 -> OK
A28: Обратный пересчёт T->V (коррекция давления ДО) и V->T (коррекция ПОСЛЕ) — в листе «Расчёт»

Sheet График
A1: Графики дистилляции (D86). Диаграмма 1 — Ветка 1 (% отгона → T_corr + полином); Диаграмма 2 — Ветка 2 (Vср, % → T_НД + полином).
A3: % отгона | B3: T_corr (эксперимент) | C3: T_полином (аппроксимация) | E3: Vср, % (Ветка 2) | F3: T_НД, °C (из НД, при 760) | G3: T_полином Ветки 2 (аппроксимация)
A4: =Расчёт!A2 -> 0 | B4: =Расчёт!F2 -> 162.5 | C4: =Расчёт!C54 -> 168.05308 | E4: =Расчёт!F27 -> 4.5 | F4: =Расчёт!A27 -> 150 | G4: =Расчёт!C81 -> T_полином, °C
A5: =Расчёт!A3 -> 5 | B5: =Расчёт!F3 -> 191 | C5: =Расчёт!C55 -> 185.61886 | E5: =Расчёт!F28 -> 6.5 | F5: =Расчёт!A28 -> 200 | G5: =Расчёт!C82 -> #VALUE!
A6: =Расчёт!A4 -> 10 | B6: =Расчёт!F4 -> 204.5 | C6: =Расчёт!C56 -> 200.90578 | E6: =Расчёт!F29 -> 9.5 | F6: =Расчёт!A29 -> 250 | G6: =Расчёт!C83
A7: =Расчёт!A5 -> 15 | B7: =Расчёт!F5 -> 210.5 | C7: =Расчёт!C57 -> 214.15234 | E7: =Расчёт!F30 -> 13.5 | F7: =Расчёт!A30 -> 300 | G7: =Расчёт!C84
A8: =Расчёт!A6 -> 20 | B8: =Расчёт!F6 -> 228 | C8: =Расчёт!C58 -> 225.59705 | E8: =Расчёт!F31 -> 17.5 | F8: =Расчёт!A31 -> 350 | G8: =Расчёт!C85
A9: =Расчёт!A7 -> 25 | B9: =Расчёт!F7 -> 235.5 | C9: =Расчёт!C59 -> 235.47841 | E9: =Расчёт!F32 | F9: =Расчёт!A32 -> 0 | G9: =Расчёт!C86
A10: =Расчёт!A8 -> 30 | B10: =Расчёт!F8 -> 244.5 | C10: =Расчёт!C60 -> 244.03493 | E10: =Расчёт!F33 | F10: =Расчёт!A33 -> 0 | G10: =Расчёт!C87
A11: =Расчёт!A9 -> 35 | B11: =Расчёт!F9 -> 250.5 | C11: =Расчёт!C61 -> 251.50513 | E11: =Расчёт!F34 | F11: =Расчёт!A34 -> 0 | G11: =Расчёт!C88
A12: =Расчёт!A10 -> 40 | B12: =Расчёт!F10 -> 257 | C12: =Расчёт!C62 -> 258.12749 | E12: =Расчёт!F35 | F12: =Расчёт!A35 -> 0 | G12: =Расчёт!C89
A13: =Расчёт!A11 -> 45 | B13: =Расчёт!F11 -> 262.5 | C13: =Расчёт!C63 -> 264.14054 | E13: =Расчёт!F36 | F13: =Расчёт!A36 -> 0 | G13: =Расчёт!C90
A14: =Расчёт!A12 -> 50 | B14: =Расчёт!F12 -> 269.5 | C14: =Расчёт!C64 -> 269.78277 | E14: =Расчёт!F37 | F14: =Расчёт!A37 -> 0 | G14: =Расчёт!C91
A15: =Расчёт!A13 -> 55 | B15: =Расчёт!F13 -> 274.5 | C15: =Расчёт!C65 -> 275.2927 | E15: =Расчёт!F38 | F15: =Расчёт!A38 -> 0 | G15: =Расчёт!C92
... A24: =Расчёт!A22 -> 100 | B24: =Расчёт!F22 -> 355.5 | C24: =Расчёт!C74 -> 358.28176 | E24: =Расчёт!F47 | F24: =Расчёт!A47 -> 0 | G24: =Расчёт!C101
A26: R² (полином Ветки 1, из листа «Расчёт»): | B26: =Расчёт!B75 -> 0.99779044 | E26: R² (полином Ветки 2, из листа «Расчёт»): | F26: =Расчёт!B102
A27: ВСПОМОГАТЕЛЬНАЯ ОБЛАСТЬ (Ветка 2): пары Vср → T_НД, собранные БЕЗ ПУСТОТ (для LINEST второй модели и второй диаграммы)
A28: Vср, % (без пустот) | B28: T_НД, °C (без пустот)
A29: =IFERROR(INDEX(Расчёт!$F$27:$F$47,SMALL(IF(ISNUMBER(Расчёт!$F$27:$F$47),ROW(Расчёт!$F$27:$F$47)-ROW(Расчёт!$F$27)+1),1)),"") -> 4.5 | B29: =IFERROR(INDEX(Расчёт!$A$27:$A$47,SMALL(IF(ISNUMBER(Расчёт!$F$27:$F$47),ROW(Расчёт!$F$27:$F$47)-ROW(Расчёт!$F$27)+1),1)),"") -> 150
A30: =IFERROR(INDEX(Расчёт!$F$27:$F$47,SMALL(IF(ISNUMBER(Расчёт!$F$27:$F$47),ROW(Расчёт!$F$27:$F$47)-ROW(Расчёт!$F$27)+1),2)),"") | B30: =IFERROR(INDEX(Расчёт!$A$27:$A$47,SMALL(IF(ISNUMBER(Расчёт!$F$27:$F$47),ROW(Расчёт!$F$27:$F$47)-ROW(Расчёт!$F$27)+1),2)),"")
A31: =IFERROR(INDEX(Расчёт!$F$27:$F$47,SMALL(IF(ISNUMBER(Расчёт!$F$27:$F$47),ROW(Расчёт!$F$27:$F$47)-ROW(Расчёт!$F$27)+1),3)),"") | B31: =IFERROR(INDEX(Расчёт!$A$27:$A$47,SMALL(IF(ISNUMBER(Расчёт!$F$27:$F$47),ROW(Расчёт!$F$27:$F$47)-ROW(Расчёт!$F$27)+1),3)),"")
A32: =IFERROR(INDEX(Расчёт!$F$27:$F$47,SMALL(IF(ISNUMBER(Расчёт!$F$27:$F$47),ROW(Расчёт!$F$27:$F$47)-ROW(Расчёт!$F$27)+1),4)),"") | B32: =IFERROR(INDEX(Расчёт!$A$27:$A$47,SMALL(IF(ISNUMBER(Расчёт!$F$27:$F$47),ROW(Расчёт!$F$27:$F$47)-ROW(Расчёт!$F$27)+1),4)),"")
A33: =IFERROR(INDEX(Расчёт!$F$27:$F$47,SMALL(IF(ISNUMBER(Расчёт!$F$27:$F$47),ROW(Расчёт!$F$27:$F$47)-ROW(Расчёт!$F$27)+1),5)),"") | B33: =IFERROR(INDEX(Расчёт!$A$27:$A$47,SMALL(IF(ISNUMBER(Расчёт!$F$27:$F$47),ROW(Расчёт!$F$27:$F$47)-ROW(Расчёт!$F$27)+1),5)),"")
A34: =IFERROR(INDEX(Расчёт!$F$27:$F$47,SMALL(IF(ISNUMBER(Расчёт!$F$27:$F$47),ROW(Расчёт!$F$27:$F$47)-ROW(Расчёт!$F$27)+1),6)),"") | B34: =IFERROR(INDEX(Расчёт!$A$27:$A$47,SMALL(IF(ISNUMBER(Расчёт!$F$27:$F$47),ROW(Расчёт!$F$27:$F$47)-ROW(Расчёт!$F$27)+1),6)),"")
A35: =IFERROR(INDEX(Расчёт!$F$27:$F$47,SMALL(IF(ISNUMBER(Расчёт!$F$27:$F$47),ROW(Расчёт!$F$27:$F$47)-ROW(Расчёт!$F$27)+1),7)),"") | B35: =IFERROR(INDEX(Расчёт!$A$27:$A$47,SMALL(IF(ISNUMBER(Расчёт!$F$27:$F$47),ROW(Расчёт!$F$27:$F$47)-ROW(Расчёт!$F$27)+1),7)),"")
A36: =IFERROR(INDEX(Расчёт!$F$27:$F$47,SMALL(IF(ISNUMBER(Расчёт!$F$27:$F$47),ROW(Расчёт!$F$27:$F$47)-ROW(Расчёт!$F$27)+1),8)),"") | B36: =IFERROR(INDEX(Расчёт!$A$27:$A$47,SMALL(IF(ISNUMBER(Расчёт!$F$27:$F$47),ROW(Расчёт!$F$27:$F$47)-ROW(Расчёт!$F$27)+1),8)),"")
A37: =IFERROR(INDEX(Расчёт!$F$27:$F$47,SMALL(IF(ISNUMBER(Расчёт!$F$27:$F$47),ROW(Расчёт!$F$27:$F$47)-ROW(Расчёт!$F$27)+1),9)),"") | B37: =IFERROR(INDEX(Расчёт!$A$27:$A$47,SMALL(IF(ISNUMBER(Расчёт!$F$27:$F$47),ROW(Расчёт!$F$27:$F$47)-ROW(Расчёт!$F$27)+1),9)),"")
A38: =IFERROR(INDEX(Расчёт!$F$27:$F$47,SMALL(IF(ISNUMBER(Расчёт!$F$27:$F$47),ROW(Расчёт!$F$27:$F$47)-ROW(Расчёт!$F$27)+1),10)),"") | B38: =IFERROR(INDEX(Расчёт!$A$27:$A$47,SMALL(IF(ISNUMBER(Расчёт!$F$27:$F$47),ROW(Расчёт!$F$27:$F$47)-ROW(Расчёт!$F$27)+1),10)),"")
A39: =IFERROR(INDEX(Расчёт!$F$27:$F$47,SMALL(IF(ISNUMBER(Расчёт!$F$27:$F$47),ROW(Расчёт!$F$27:$F$47)-ROW(Расчёт!$F$27)+1),11)),"") | B39: =IFERROR(INDEX(Расчёт!$A$27:$A$47,SMALL(IF(ISNUMBER(Расчёт!$F$27:$F$47),ROW(Расчёт!$F$27:$F$47)-ROW(Расчёт!$F$27)+1),11)),"")
A40: =IFERROR(INDEX(Расчёт!$F$27:$F$47,SMALL(IF(ISNUMBER(Расчёт!$F$27:$F$47),ROW(Расчёт!$F$27:$F$47)-ROW(Расчёт!$F$27)+1),12)),"") | B40: =IFERROR(INDEX(Расчёт!$A$27:$A$47,SMALL(IF(ISNUMBER(Расчёт!$F$27:$F$47),ROW(Расчёт!$F$27:$F$47)-ROW(Расчёт!$F$27)+1),12)),"")
A41: =IFERROR(INDEX(Расчёт!$F$27:$F$47,SMALL(IF(ISNUMBER(Расчёт!$F$27:$F$47),ROW(Расчёт!$F$27:$F$47)-ROW(Расчёт!$F$27)+1),13)),"") | B41: =IFERROR(INDEX(Расчёт!$A$27:$A$47,SMALL(IF(ISNUMBER(Расчёт!$F$27:$F$47),ROW(Расчёт!$F$27:$F$47)-ROW(Расчёт!$F$27)+1),13)),"")
A42: =IFERROR(INDEX(Расчёт!$F$27:$F$47,SMALL(IF(ISNUMBER(Расчёт!$F$27:$F$47),ROW(Расчёт!$F$27:$F$47)-ROW(Расчёт!$F$27)+1),14)),"") | B42: =IFERROR(INDEX(Расчёт!$A$27:$A$47,SMALL(IF(ISNUMBER(Расчёт!$F$27:$F$47),ROW(Расчёт!$F$27:$F$47)-ROW(Расчёт!$F$27)+1),14)),"")
A43: =IFERROR(INDEX(Расчёт!$F$27:$F$47,SMALL(IF(ISNUMBER(Расчёт!$F$27:$F$47),ROW(Расчёт!$F$27:$F$47)-ROW(Расчёт!$F$27)+1),15)),"") | B43: =IFERROR(INDEX(Расчёт!$A$27:$A$47,SMALL(IF(ISNUMBER(Расчёт!$F$27:$F$47),ROW(Расчёт!$F$27:$F$47)-ROW(Расчёт!$F$27)+1),15)),"")
A44: =IFERROR(INDEX(Расчёт!$F$27:$F$47,SMALL(IF(ISNUMBER(Расчёт!$F$27:$F$47),ROW(Расчёт!$F$27:$F$47)-ROW(Расчёт!$F$27)+1),16)),"") | B44: =IFERROR(INDEX(Расчёт!$A$27:$A$47,SMALL(IF(ISNUMBER(Расчёт!$F$27:$F$47),ROW(Расчёт!$F$27:$F$47)-ROW(Расчёт!$F$27)+1),16)),"")
A45: =IFERROR(INDEX(Расчёт!$F$27:$F$47,SMALL(IF(ISNUMBER(Расчёт!$F$27:$F$47),ROW(Расчёт!$F$27:$F$47)-ROW(Расчёт!$F$27)+1),17)),"") | B45: =IFERROR(INDEX(Расчёт!$A$27:$A$47,SMALL(IF(ISNUMBER(Расчёт!$F$27:$F$47),ROW(Расчёт!$F$27:$F$47)-ROW(Расчёт!$F$27)+1),17)),"")
A46: =IFERROR(INDEX(Расчёт!$F$27:$F$47,SMALL(IF(ISNUMBER(Расчёт!$F$27:$F$47),ROW(Расчёт!$F$27:$F$47)-ROW(Расчёт!$F$27)+1),18)),"") | B46: =IFERROR(INDEX(Расчёт!$A$27:$A$47,SMALL(IF(ISNUMBER(Расчёт!$F$27:$F$47),ROW(Расчёт!$F$27:$F$47)-ROW(Расчёт!$F$27)+1),18)),"")
A47: =IFERROR(INDEX(Расчёт!$F$27:$F$47,SMALL(IF(ISNUMBER(Расчёт!$F$27:$F$47),ROW(Расчёт!$F$27:$F$47)-ROW(Расчёт!$F$27)+1),19)),"") | B47: =IFERROR(INDEX(Расчёт!$A$27:$A$47,SMALL(IF(ISNUMBER(Расчёт!$F$27:$F$47),ROW(Расчёт!$F$27:$F$47)-ROW(Расчёт!$F$27)+1),19)),"")
A48: =IFERROR(INDEX(Расчёт!$F$27:$F$47,SMALL(IF(ISNUMBER(Расчёт!$F$27:$F$47),ROW(Расчёт!$F$27:$F$47)-ROW(Расчёт!$F$27)+1),20)),"") | B48: =IFERROR(INDEX(Расчёт!$A$27:$A$47,SMALL(IF(ISNUMBER(Расчёт!$F$27:$F$47),ROW(Расчёт!$F$27:$F$47)-ROW(Расчёт!$F$27)+1),20)),"")
A49: =IFERROR(INDEX(Расчёт!$F$27:$F$47,SMALL(IF(ISNUMBER(Расчёт!$F$27:$F$47),ROW(Расчёт!$F$27:$F$47)-ROW(Расчёт!$F$27)+1),21)),"") | B49: =IFERROR(INDEX(Расчёт!$A$27:$A$47,SMALL(IF(ISNUMBER(Расчёт!$F$27:$F$47),ROW(Расчёт!$F$27:$F$47)-ROW(Расчёт!$F$27)+1),21)),"")
