Workbook

Sheet О книге
A1: Книга | B1: ASTM D1160 расчёт (вакуумная)
A2: Версия | B2: 3.11.0
A3: Дата генерации | B3: 2026-10-07
A4: Стандарт | B4: ASTM D1160-18
A5: Метод | B5: Определение фракционного состава при пониженном давлении, AET
A6: Источник расчёта | B6: fraction_lib (Python)
A7: Автор/Разработчик | B7: лаборатория (заполнить)
A8: Проверил
A9: Утвердил
A10: Примечание | B10: Книга генерируется скриптом — правки вручную не вносить
A11: Политика пустых ячеек (TD-007) | B11: Пустая ячейка = не введено (НЕ РАССЧИТАНО). Ошибка формулы = ошибка расчёта. Статус контроля: НЕ РАССЧИТАНО / OK / НЕ СООТВЕТСТВУЕТ.
A12: Критерий K (ГСО) | B12: K = (1/√2)·√(R² − r²/2) — из свидетельства на ГСО, НЕ изменять
A13: Коэффициент 0,84 (ОК) | B13: Из сборника «Метрология в химическом анализе» (АНАЛИТИКА), НЕ изменять

Sheet Ввод
A1: P разгонки, мм рт.ст. | B1: 10 | C1: P атм, мм рт.ст. | D1: 750 | F1: Объём образца, мл | G1: 100
A3: % отгона | B3: V, мл | C3: T1, °C | D3: T2, °C
A4: =IF(ISNUMBER(B4),ROUND(B4/$G$1*100,1),"НК")
A5: =IF(ISNUMBER(B5),ROUND(B5/$G$1*100,1),"5")
A6: =IF(ISNUMBER(B6),ROUND(B6/$G$1*100,1),"10")
A7: =IF(ISNUMBER(B7),ROUND(B7/$G$1*100,1),"15")
A8: =IF(ISNUMBER(B8),ROUND(B8/$G$1*100,1),"20")
A9: =IF(ISNUMBER(B9),ROUND(B9/$G$1*100,1),"25")
A10: =IF(ISNUMBER(B10),ROUND(B10/$G$1*100,1),"30")
A11: =IF(ISNUMBER(B11),ROUND(B11/$G$1*100,1),"35")
A12: =IF(ISNUMBER(B12),ROUND(B12/$G$1*100,1),"40")
A13: =IF(ISNUMBER(B13),ROUND(B13/$G$1*100,1),"45")
A14: =IF(ISNUMBER(B14),ROUND(B14/$G$1*100,1),"50")
A15: =IF(ISNUMBER(B15),ROUND(B15/$G$1*100,1),"55")
A16: =IF(ISNUMBER(B16),ROUND(B16/$G$1*100,1),"60")
A17: =IF(ISNUMBER(B17),ROUND(B17/$G$1*100,1),"65")
A18: =IF(ISNUMBER(B18),ROUND(B18/$G$1*100,1),"70")
A19: =IF(ISNUMBER(B19),ROUND(B19/$G$1*100,1),"75")
A20: =IF(ISNUMBER(B20),ROUND(B20/$G$1*100,1),"80")
A21: =IF(ISNUMBER(B21),ROUND(B21/$G$1*100,1),"85")
A22: =IF(ISNUMBER(B22),ROUND(B22/$G$1*100,1),"90")
A23: =IF(ISNUMBER(B23),ROUND(B23/$G$1*100,1),"95")
A24: =IF(ISNUMBER(B24),ROUND(B24/$G$1*100,1),"КК")

Sheet Расчёт
A1: % отгона | B1: T1 | C1: T2 | D1: Хср | E1: AET (Максвелл-Боннелл) | F1: r (12.2) | G1: R (12.2) | H1: |T1-T2| | I1: K (ГСО) | J1: 0.84R (ОК) | K1: Статус | M1: ВЕТКА 1 — ЗАДАНЫ ОБЪЁМЫ (выпаривание): % отгона → T1/T2 → поправка давления → T_corr (приведена к 760). Ввод: T1/T2 и объёмы в «Ввод» (зелёные ячейки), Ввод!$G$1 = объём образца, мл.
A2: 0 | B2: ='Ввод'!C4 | C2: ='Ввод'!D4 | D2: =IF(OR(ISBLANK(B2),ISBLANK(C2)),B2,MROUND((B2+C2)/2,0.5)) | E2: =IF(ISBLANK(D2),"",IF(Ввод!$B$1<1,"P<1 мм — вне диапазона (A7.2)",748.1*IF(Ввод!$B$1>=2,(5.994295-0.972546*LOG10(Ввод!$B$1))/(2663.129-95.76*LOG10(Ввод!$B$1)),(6.761559-0.987672*LOG10(Ввод!$B$1))/(3000.538-43.00*LOG10(Ввод!$B$1)))/(1/(D2+273.1)+0.3861*IF(Ввод!$B$1>=2,(5.994295-0.972546*LOG10(Ввод!$B$1))/(2663.129-95.76*LOG10(Ввод!$B$1)),(6.761559-0.987672*LOG10(Ввод!$B$1))/(3000.538-43.00*LOG10(Ввод!$B$1)))-0.00051606)-273.1)) | F2: =IF(OR(ISBLANK(E2),ISBLANK(E3)),"",IF(Ввод!$B$1<=10,(1-LOG10(Ввод!$B$1))*2.9+LOG10(Ввод!$B$1)*2.8,2.8)*(EXP(1)*EXP(IF(Ввод!$B$1<=10,(1-LOG10(Ввод!$B$1))*2.372+LOG10(Ввод!$B$1)*2.246,2.246)+IF(Ввод!$B$1<=10,(1-LOG10(Ввод!$B$1))*0+LOG10(Ввод!$B$1)*0,0)*LN(1.8*(ABS(E3-E2)/5))))/1.8) | G2: =IF(OR(ISBLANK(E2),ISBLANK(E3)),"",IF(Ввод!$B$1<=10,(1-LOG10(Ввод!$B$1))*3.0+LOG10(Ввод!$B$1)*2.9,2.9)*(EXP(1)*EXP(IF(Ввод!$B$1<=10,(1-LOG10(Ввод!$B$1))*3.512+LOG10(Ввод!$B$1)*3.424,3.424)+IF(Ввод!$B$1<=10,(1-LOG10(Ввод!$B$1))*0+LOG10(Ввод!$B$1)*0,0)*LN(1.8*(ABS(E3-E2)/5))))/1.8) | H2: =IF(OR(ISBLANK(B2),ISBLANK(C2)),"",ABS(B2-C2)) | I2: =(1/SQRT(2))*SQRT(G2^2-F2^2/2) | J2: =0.84*G2 | K2: =IF(OR(ISBLANK(B2),ISBLANK(C2)),"НЕ РАССЧИТАНО",IF(AND(ISNUMBER(H2),ISNUMBER(F2)),IF(H2<=F2,"OK","НЕ СООТВЕТСТВУЕТ"),"НЕ РАССЧИТАНО"))
A3: 5 | B3: ='Ввод'!C5 | C3: ='Ввод'!D5 | D3: =IF(OR(ISBLANK(B3),ISBLANK(C3)),B3,MROUND((B3+C3)/2,0.5)) | E3: =IF(ISBLANK(D3),"",IF(Ввод!$B$1<1,"P<1 мм — вне диапазона (A7.2)",748.1*IF(Ввод!$B$1>=2,(5.994295-0.972546*LOG10(Ввод!$B$1))/(2663.129-95.76*LOG10(Ввод!$B$1)),(6.761559-0.987672*LOG10(Ввод!$B$1))/(3000.538-43.00*LOG10(Ввод!$B$1)))/(1/(D3+273.1)+0.3861*IF(Ввод!$B$1>=2,(5.994295-0.972546*LOG10(Ввод!$B$1))/(2663.129-95.76*LOG10(Ввод!$B$1)),(6.761559-0.987672*LOG10(Ввод!$B$1))/(3000.538-43.00*LOG10(Ввод!$B$1)))-0.00051606)-273.1)) | F3: =IF(OR(ISBLANK(E3),ISBLANK(E4)),"",IF(Ввод!$B$1<=10,(1-LOG10(Ввод!$B$1))*2.9+LOG10(Ввод!$B$1)*2.8,2.8)*(EXP(1)*EXP(IF(Ввод!$B$1<=10,(1-LOG10(Ввод!$B$1))*0.439+LOG10(Ввод!$B$1)*0.24,0.24)+IF(Ввод!$B$1<=10,(1-LOG10(Ввод!$B$1))*0.241+LOG10(Ввод!$B$1)*0.35,0.35)*LN(1.8*(ABS(E4-E2)/(A4-A2)))))/1.8) | G3: =IF(OR(ISBLANK(E3),ISBLANK(E4)),"",IF(Ввод!$B$1<=10,(1-LOG10(Ввод!$B$1))*3.3+LOG10(Ввод!$B$1)*3.2,3.2)*(EXP(1)*EXP(IF(Ввод!$B$1<=10,(1-LOG10(Ввод!$B$1))*1.338+LOG10(Ввод!$B$1)*1.415,1.415)+IF(Ввод!$B$1<=10,(1-LOG10(Ввод!$B$1))*0.639+LOG10(Ввод!$B$1)*0.409,0.409)*LN(1.8*(ABS(E4-E2)/(A4-A2)))))/1.8) | H3: =IF(OR(ISBLANK(B3),ISBLANK(C3)),"",ABS(B3-C3)) | I3: =(1/SQRT(2))*SQRT(G3^2-F3^2/2) | J3: =0.84*G3 | K3: =IF(OR(ISBLANK(B3),ISBLANK(C3)),"НЕ РАССЧИТАНО",IF(AND(ISNUMBER(H3),ISNUMBER(F3)),IF(H3<=F3,"OK","НЕ СООТВЕТСТВУЕТ"),"НЕ РАССЧИТАНО"))
A4: 10 | B4: ='Ввод'!C6 | C4: ='Ввод'!D6 | D4: =IF(OR(ISBLANK(B4),ISBLANK(C4)),B4,MROUND((B4+C4)/2,0.5)) | E4: =IF(ISBLANK(D4),"",IF(Ввод!$B$1<1,"P<1 мм — вне диапазона (A7.2)",748.1*IF(Ввод!$B$1>=2,(5.994295-0.972546*LOG10(Ввод!$B$1))/(2663.129-95.76*LOG10(Ввод!$B$1)),(6.761559-0.987672*LOG10(Ввод!$B$1))/(3000.538-43.00*LOG10(Ввод!$B$1)))/(1/(D4+273.1)+0.3861*IF(Ввод!$B$1>=2,(5.994295-0.972546*LOG10(Ввод!$B$1))/(2663.129-95.76*LOG10(Ввод!$B$1)),(6.761559-0.987672*LOG10(Ввод!$B$1))/(3000.538-43.00*LOG10(Ввод!$B$1)))-0.00051606)-273.1)) | F4: =IF(OR(ISBLANK(E4),ISBLANK(E5)),"",IF(Ввод!$B$1<=10,(1-LOG10(Ввод!$B$1))*2.9+LOG10(Ввод!$B$1)*2.8,2.8)*(EXP(1)*EXP(IF(Ввод!$B$1<=10,(1-LOG10(Ввод!$B$1))*0.439+LOG10(Ввод!$B$1)*0.24,0.24)+IF(Ввод!$B$1<=10,(1-LOG10(Ввод!$B$1))*0.241+LOG10(Ввод!$B$1)*0.35,0.35)*LN(1.8*(ABS(E5-E3)/(A5-A3)))))/1.8) | G4: =IF(OR(ISBLANK(E4),ISBLANK(E5)),"",IF(Ввод!$B$1<=10,(1-LOG10(Ввод!$B$1))*3.3+LOG10(Ввод!$B$1)*3.2,3.2)*(EXP(1)*EXP(IF(Ввод!$B$1<=10,(1-LOG10(Ввод!$B$1))*1.338+LOG10(Ввод!$B$1)*1.415,1.415)+IF(Ввод!$B$1<=10,(1-LOG10(Ввод!$B$1))*0.639+LOG10(Ввод!$B$1)*0.409,0.409)*LN(1.8*(ABS(E5-E3)/(A5-A3)))))/1.8) | H4: =IF(OR(ISBLANK(B4),ISBLANK(C4)),"",ABS(B4-C4)) | I4: =(1/SQRT(2))*SQRT(G4^2-F4^2/2) | J4: =0.84*G4 | K4: =IF(OR(ISBLANK(B4),ISBLANK(C4)),"НЕ РАССЧИТАНО",IF(AND(ISNUMBER(H4),ISNUMBER(F4)),IF(H4<=F4,"OK","НЕ СООТВЕТСТВУЕТ"),"НЕ РАССЧИТАНО"))
A5: 15 | B5: ='Ввод'!C7 | C5: ='Ввод'!D7 | D5: =IF(OR(ISBLANK(B5),ISBLANK(C5)),B5,MROUND((B5+C5)/2,0.5)) | E5: =IF(ISBLANK(D5),"",IF(Ввод!$B$1<1,"P<1 мм — вне диапазона (A7.2)",748.1*IF(Ввод!$B$1>=2,(5.994295-0.972546*LOG10(Ввод!$B$1))/(2663.129-95.76*LOG10(Ввод!$B$1)),(6.761559-0.987672*LOG10(Ввод!$B$1))/(3000.538-43.00*LOG10(Ввод!$B$1)))/(1/(D5+273.1)+0.3861*IF(Ввод!$B$1>=2,(5.994295-0.972546*LOG10(Ввод!$B$1))/(2663.129-95.76*LOG10(Ввод!$B$1)),(6.761559-0.987672*LOG10(Ввод!$B$1))/(3000.538-43.00*LOG10(Ввод!$B$1)))-0.00051606)-273.1)) | F5: =IF(OR(ISBLANK(E5),ISBLANK(E6)),"",IF(Ввод!$B$1<=10,(1-LOG10(Ввод!$B$1))*2.9+LOG10(Ввод!$B$1)*2.8,2.8)*(EXP(1)*EXP(IF(Ввод!$B$1<=10,(1-LOG10(Ввод!$B$1))*0.439+LOG10(Ввод!$B$1)*0.24,0.24)+IF(Ввод!$B$1<=10,(1-LOG10(Ввод!$B$1))*0.241+LOG10(Ввод!$B$1)*0.35,0.35)*LN(1.8*(ABS(E6-E4)/(A6-A4)))))/1.8) | G5: =IF(OR(ISBLANK(E5),ISBLANK(E6)),"",IF(Ввод!$B$1<=10,(1-LOG10(Ввод!$B$1))*3.3+LOG10(Ввод!$B$1)*3.2,3.2)*(EXP(1)*EXP(IF(Ввод!$B$1<=10,(1-LOG10(Ввод!$B$1))*1.338+LOG10(Ввод!$B$1)*1.415,1.415)+IF(Ввод!$B$1<=10,(1-LOG10(Ввод!$B$1))*0.639+LOG10(Ввод!$B$1)*0.409,0.409)*LN(1.8*(ABS(E6-E4)/(A6-A4)))))/1.8) | H5: =IF(OR(ISBLANK(B5),ISBLANK(C5)),"",ABS(B5-C5)) | I5: =(1/SQRT(2))*SQRT(G5^2-F5^2/2) | J5: =0.84*G5 | K5: =IF(OR(ISBLANK(B5),ISBLANK(C5)),"НЕ РАССЧИТАНО",IF(AND(ISNUMBER(H5),ISNUMBER(F5)),IF(H5<=F5,"OK","НЕ СООТВЕТСТВУЕТ"),"НЕ РАССЧИТАНО"))
A6: 20 | B6: ='Ввод'!C8 | C6: ='Ввод'!D8 | D6: =IF(OR(ISBLANK(B6),ISBLANK(C6)),B6,MROUND((B6+C6)/2,0.5)) | E6: =IF(ISBLANK(D6),"",IF(Ввод!$B$1<1,"P<1 мм — вне диапазона (A7.2)",748.1*IF(Ввод!$B$1>=2,(5.994295-0.972546*LOG10(Ввод!$B$1))/(2663.129-95.76*LOG10(Ввод!$B$1)),(6.761559-0.987672*LOG10(Ввод!$B$1))/(3000.538-43.00*LOG10(Ввод!$B$1)))/(1/(D6+273.1)+0.3861*IF(Ввод!$B$1>=2,(5.994295-0.972546*LOG10(Ввод!$B$1))/(2663.129-95.76*LOG10(Ввод!$B$1)),(6.761559-0.987672*LOG10(Ввод!$B$1))/(3000.538-43.00*LOG10(Ввод!$B$1)))-0.00051606)-273.1)) | F6: =IF(OR(ISBLANK(E6),ISBLANK(E7)),"",IF(Ввод!$B$1<=10,(1-LOG10(Ввод!$B$1))*2.9+LOG10(Ввод!$B$1)*2.8,2.8)*(EXP(1)*EXP(IF(Ввод!$B$1<=10,(1-LOG10(Ввод!$B$1))*0.439+LOG10(Ввод!$B$1)*0.24,0.24)+IF(Ввод!$B$1<=10,(1-LOG10(Ввод!$B$1))*0.241+LOG10(Ввод!$B$1)*0.35,0.35)*LN(1.8*(ABS(E7-E5)/(A7-A5)))))/1.8) | G6: =IF(OR(ISBLANK(E6),ISBLANK(E7)),"",IF(Ввод!$B$1<=10,(1-LOG10(Ввод!$B$1))*3.3+LOG10(Ввод!$B$1)*3.2,3.2)*(EXP(1)*EXP(IF(Ввод!$B$1<=10,(1-LOG10(Ввод!$B$1))*1.338+LOG10(Ввод!$B$1)*1.415,1.415)+IF(Ввод!$B$1<=10,(1-LOG10(Ввод!$B$1))*0.639+LOG10(Ввод!$B$1)*0.409,0.409)*LN(1.8*(ABS(E7-E5)/(A7-A5)))))/1.8) | H6: =IF(OR(ISBLANK(B6),ISBLANK(C6)),"",ABS(B6-C6)) | I6: =(1/SQRT(2))*SQRT(G6^2-F6^2/2) | J6: =0.84*G6 | K6: =IF(OR(ISBLANK(B6),ISBLANK(C6)),"НЕ РАССЧИТАНО",IF(AND(ISNUMBER(H6),ISNUMBER(F6)),IF(H6<=F6,"OK","НЕ СООТВЕТСТВУЕТ"),"НЕ РАССЧИТАНО"))
A7: 25 | B7: ='Ввод'!C9 | C7: ='Ввод'!D9 | D7: =IF(OR(ISBLANK(B7),ISBLANK(C7)),B7,MROUND((B7+C7)/2,0.5)) | E7: =IF(ISBLANK(D7),"",IF(Ввод!$B$1<1,"P<1 мм — вне диапазона (A7.2)",748.1*IF(Ввод!$B$1>=2,(5.994295-0.972546*LOG10(Ввод!$B$1))/(2663.129-95.76*LOG10(Ввод!$B$1)),(6.761559-0.987672*LOG10(Ввод!$B$1))/(3000.538-43.00*LOG10(Ввод!$B$1)))/(1/(D7+273.1)+0.3861*IF(Ввод!$B$1>=2,(5.994295-0.972546*LOG10(Ввод!$B$1))/(2663.129-95.76*LOG10(Ввод!$B$1)),(6.761559-0.987672*LOG10(Ввод!$B$1))/(3000.538-43.00*LOG10(Ввод!$B$1)))-0.00051606)-273.1)) | F7: =IF(OR(ISBLANK(E7),ISBLANK(E8)),"",IF(Ввод!$B$1<=10,(1-LOG10(Ввод!$B$1))*2.9+LOG10(Ввод!$B$1)*2.8,2.8)*(EXP(1)*EXP(IF(Ввод!$B$1<=10,(1-LOG10(Ввод!$B$1))*0.439+LOG10(Ввод!$B$1)*0.24,0.24)+IF(Ввод!$B$1<=10,(1-LOG10(Ввод!$B$1))*0.241+LOG10(Ввод!$B$1)*0.35,0.35)*LN(1.8*(ABS(E8-E6)/(A8-A6)))))/1.8) | G7: =IF(OR(ISBLANK(E7),ISBLANK(E8)),"",IF(Ввод!$B$1<=10,(1-LOG10(Ввод!$B$1))*3.3+LOG10(Ввод!$B$1)*3.2,3.2)*(EXP(1)*EXP(IF(Ввод!$B$1<=10,(1-LOG10(Ввод!$B$1))*1.338+LOG10(Ввод!$B$1)*1.415,1.415)+IF(Ввод!$B$1<=10,(1-LOG10(Ввод!$B$1))*0.639+LOG10(Ввод!$B$1)*0.409,0.409)*LN(1.8*(ABS(E8-E6)/(A8-A6)))))/1.8) | H7: =IF(OR(ISBLANK(B7),ISBLANK(C7)),"",ABS(B7-C7)) | I7: =(1/SQRT(2))*SQRT(G7^2-F7^2/2) | J7: =0.84*G7 | K7: =IF(OR(ISBLANK(B7),ISBLANK(C7)),"НЕ РАССЧИТАНО",IF(AND(ISNUMBER(H7),ISNUMBER(F7)),IF(H7<=F7,"OK","НЕ СООТВЕТСТВУЕТ"),"НЕ РАССЧИТАНО"))
A8: 30 | B8: ='Ввод'!C10 | C8: ='Ввод'!D10 | D8: =IF(OR(ISBLANK(B8),ISBLANK(C8)),B8,MROUND((B8+C8)/2,0.5)) | E8: =IF(ISBLANK(D8),"",IF(Ввод!$B$1<1,"P<1 мм — вне диапазона (A7.2)",748.1*IF(Ввод!$B$1>=2,(5.994295-0.972546*LOG10(Ввод!$B$1))/(2663.129-95.76*LOG10(Ввод!$B$1)),(6.761559-0.987672*LOG10(Ввод!$B$1))/(3000.538-43.00*LOG10(Ввод!$B$1)))/(1/(D8+273.1)+0.3861*IF(Ввод!$B$1>=2,(5.994295-0.972546*LOG10(Ввод!$B$1))/(2663.129-95.76*LOG10(Ввод!$B$1)),(6.761559-0.987672*LOG10(Ввод!$B$1))/(3000.538-43.00*LOG10(Ввод!$B$1)))-0.00051606)-273.1)) | F8: =IF(OR(ISBLANK(E8),ISBLANK(E9)),"",IF(Ввод!$B$1<=10,(1-LOG10(Ввод!$B$1))*2.9+LOG10(Ввод!$B$1)*2.8,2.8)*(EXP(1)*EXP(IF(Ввод!$B$1<=10,(1-LOG10(Ввод!$B$1))*0.439+LOG10(Ввод!$B$1)*0.24,0.24)+IF(Ввод!$B$1<=10,(1-LOG10(Ввод!$B$1))*0.241+LOG10(Ввод!$B$1)*0.35,0.35)*LN(1.8*(ABS(E9-E7)/(A9-A7)))))/1.8) | G8: =IF(OR(ISBLANK(E8),ISBLANK(E9)),"",IF(Ввод!$B$1<=10,(1-LOG10(Ввод!$B$1))*3.3+LOG10(Ввод!$B$1)*3.2,3.2)*(EXP(1)*EXP(IF(Ввод!$B$1<=10,(1-LOG10(Ввод!$B$1))*1.338+LOG10(Ввод!$B$1)*1.415,1.415)+IF(Ввод!$B$1<=10,(1-LOG10(Ввод!$B$1))*0.639+LOG10(Ввод!$B$1)*0.409,0.409)*LN(1.8*(ABS(E9-E7)/(A9-A7)))))/1.8) | H8: =IF(OR(ISBLANK(B8),ISBLANK(C8)),"",ABS(B8-C8)) | I8: =(1/SQRT(2))*SQRT(G8^2-F8^2/2) | J8: =0.84*G8 | K8: =IF(OR(ISBLANK(B8),ISBLANK(C8)),"НЕ РАССЧИТАНО",IF(AND(ISNUMBER(H8),ISNUMBER(F8)),IF(H8<=F8,"OK","НЕ СООТВЕТСТВУЕТ"),"НЕ РАССЧИТАНО"))
A9: 35 | B9: ='Ввод'!C11 | C9: ='Ввод'!D11 | D9: =IF(OR(ISBLANK(B9),ISBLANK(C9)),B9,MROUND((B9+C9)/2,0.5)) | E9: =IF(ISBLANK(D9),"",IF(Ввод!$B$1<1,"P<1 мм — вне диапазона (A7.2)",748.1*IF(Ввод!$B$1>=2,(5.994295-0.972546*LOG10(Ввод!$B$1))/(2663.129-95.76*LOG10(Ввод!$B$1)),(6.761559-0.987672*LOG10(Ввод!$B$1))/(3000.538-43.00*LOG10(Ввод!$B$1)))/(1/(D9+273.1)+0.3861*IF(Ввод!$B$1>=2,(5.994295-0.972546*LOG10(Ввод!$B$1))/(2663.129-95.76*LOG10(Ввод!$B$1)),(6.761559-0.987672*LOG10(Ввод!$B$1))/(3000.538-43.00*LOG10(Ввод!$B$1)))-0.00051606)-273.1)) | F9: =IF(OR(ISBLANK(E9),ISBLANK(E10)),"",IF(Ввод!$B$1<=10,(1-LOG10(Ввод!$B$1))*2.9+LOG10(Ввод!$B$1)*2.8,2.8)*(EXP(1)*EXP(IF(Ввод!$B$1<=10,(1-LOG10(Ввод!$B$1))*0.439+LOG10(Ввод!$B$1)*0.24,0.24)+IF(Ввод!$B$1<=10,(1-LOG10(Ввод!$B$1))*0.241+LOG10(Ввод!$B$1)*0.35,0.35)*LN(1.8*(ABS(E10-E8)/(A10-A8)))))/1.8) | G9: =IF(OR(ISBLANK(E9),ISBLANK(E10)),"",IF(Ввод!$B$1<=10,(1-LOG10(Ввод!$B$1))*3.3+LOG10(Ввод!$B$1)*3.2,3.2)*(EXP(1)*EXP(IF(Ввод!$B$1<=10,(1-LOG10(Ввод!$B$1))*1.338+LOG10(Ввод!$B$1)*1.415,1.415)+IF(Ввод!$B$1<=10,(1-LOG10(Ввод!$B$1))*0.639+LOG10(Ввод!$B$1)*0.409,0.409)*LN(1.8*(ABS(E10-E8)/(A10-A8)))))/1.8) | H9: =IF(OR(ISBLANK(B9),ISBLANK(C9)),"",ABS(B9-C9)) | I9: =(1/SQRT(2))*SQRT(G9^2-F9^2/2) | J9: =0.84*G9 | K9: =IF(OR(ISBLANK(B9),ISBLANK(C9)),"НЕ РАССЧИТАНО",IF(AND(ISNUMBER(H9),ISNUMBER(F9)),IF(H9<=F9,"OK","НЕ СООТВЕТСТВУЕТ"),"НЕ РАССЧИТАНО"))
A10: 40 | B10: ='Ввод'!C12 | C10: ='Ввод'!D12 | D10: =IF(OR(ISBLANK(B10),ISBLANK(C10)),B10,MROUND((B10+C10)/2,0.5)) | E10: =IF(ISBLANK(D10),"",IF(Ввод!$B$1<1,"P<1 мм — вне диапазона (A7.2)",748.1*IF(Ввод!$B$1>=2,(5.994295-0.972546*LOG10(Ввод!$B$1))/(2663.129-95.76*LOG10(Ввод!$B$1)),(6.761559-0.987672*LOG10(Ввод!$B$1))/(3000.538-43.00*LOG10(Ввод!$B$1)))/(1/(D10+273.1)+0.3861*IF(Ввод!$B$1>=2,(5.994295-0.972546*LOG10(Ввод!$B$1))/(2663.129-95.76*LOG10(Ввод!$B$1)),(6.761559-0.987672*LOG10(Ввод!$B$1))/(3000.538-43.00*LOG10(Ввод!$B$1)))-0.00051606)-273.1)) | F10: =IF(OR(ISBLANK(E10),ISBLANK(E11)),"",IF(Ввод!$B$1<=10,(1-LOG10(Ввод!$B$1))*2.9+LOG10(Ввод!$B$1)*2.8,2.8)*(EXP(1)*EXP(IF(Ввод!$B$1<=10,(1-LOG10(Ввод!$B$1))*0.439+LOG10(Ввод!$B$1)*0.24,0.24)+IF(Ввод!$B$1<=10,(1-LOG10(Ввод!$B$1))*0.241+LOG10(Ввод!$B$1)*0.35,0.35)*LN(1.8*(ABS(E11-E9)/(A11-A9)))))/1.8) | G10: =IF(OR(ISBLANK(E10),ISBLANK(E11)),"",IF(Ввод!$B$1<=10,(1-LOG10(Ввод!$B$1))*3.3+LOG10(Ввод!$B$1)*3.2,3.2)*(EXP(1)*EXP(IF(Ввод!$B$1<=10,(1-LOG10(Ввод!$B$1))*1.338+LOG10(Ввод!$B$1)*1.415,1.415)+IF(Ввод!$B$1<=10,(1-LOG10(Ввод!$B$1))*0.639+LOG10(Ввод!$B$1)*0.409,0.409)*LN(1.8*(ABS(E11-E9)/(A11-A9)))))/1.8) | H10: =IF(OR(ISBLANK(B10),ISBLANK(C10)),"",ABS(B10-C10)) | I10: =(1/SQRT(2))*SQRT(G10^2-F10^2/2) | J10: =0.84*G10 | K10: =IF(OR(ISBLANK(B10),ISBLANK(C10)),"НЕ РАССЧИТАНО",IF(AND(ISNUMBER(H10),ISNUMBER(F10)),IF(H10<=F10,"OK","НЕ СООТВЕТСТВУЕТ"),"НЕ РАССЧИТАНО"))
A11: 45 | B11: ='Ввод'!C13 | C11: ='Ввод'!D13 | D11: =IF(OR(ISBLANK(B11),ISBLANK(C11)),B11,MROUND((B11+C11)/2,0.5)) | E11: =IF(ISBLANK(D11),"",IF(Ввод!$B$1<1,"P<1 мм — вне диапазона (A7.2)",748.1*IF(Ввод!$B$1>=2,(5.994295-0.972546*LOG10(Ввод!$B$1))/(2663.129-95.76*LOG10(Ввод!$B$1)),(6.761559-0.987672*LOG10(Ввод!$B$1))/(3000.538-43.00*LOG10(Ввод!$B$1)))/(1/(D11+273.1)+0.3861*IF(Ввод!$B$1>=2,(5.994295-0.972546*LOG10(Ввод!$B$1))/(2663.129-95.76*LOG10(Ввод!$B$1)),(6.761559-0.987672*LOG10(Ввод!$B$1))/(3000.538-43.00*LOG10(Ввод!$B$1)))-0.00051606)-273.1)) | F11: =IF(OR(ISBLANK(E11),ISBLANK(E12)),"",IF(Ввод!$B$1<=10,(1-LOG10(Ввод!$B$1))*2.9+LOG10(Ввод!$B$1)*2.8,2.8)*(EXP(1)*EXP(IF(Ввод!$B$1<=10,(1-LOG10(Ввод!$B$1))*0.439+LOG10(Ввод!$B$1)*0.24,0.24)+IF(Ввод!$B$1<=10,(1-LOG10(Ввод!$B$1))*0.241+LOG10(Ввод!$B$1)*0.35,0.35)*LN(1.8*(ABS(E12-E10)/(A12-A10)))))/1.8) | G11: =IF(OR(ISBLANK(E11),ISBLANK(E12)),"",IF(Ввод!$B$1<=10,(1-LOG10(Ввод!$B$1))*3.3+LOG10(Ввод!$B$1)*3.2,3.2)*(EXP(1)*EXP(IF(Ввод!$B$1<=10,(1-LOG10(Ввод!$B$1))*1.338+LOG10(Ввод!$B$1)*1.415,1.415)+IF(Ввод!$B$1<=10,(1-LOG10(Ввод!$B$1))*0.639+LOG10(Ввод!$B$1)*0.409,0.409)*LN(1.8*(ABS(E12-E10)/(A12-A10)))))/1.8) | H11: =IF(OR(ISBLANK(B11),ISBLANK(C11)),"",ABS(B11-C11)) | I11: =(1/SQRT(2))*SQRT(G11^2-F11^2/2) | J11: =0.84*G11 | K11: =IF(OR(ISBLANK(B11),ISBLANK(C11)),"НЕ РАССЧИТАНО",IF(AND(ISNUMBER(H11),ISNUMBER(F11)),IF(H11<=F11,"OK","НЕ СООТВЕТСТВУЕТ"),"НЕ РАССЧИТАНО"))
A12: 50 | B12: ='Ввод'!C14 | C12: ='Ввод'!D14 | D12: =IF(OR(ISBLANK(B12),ISBLANK(C12)),B12,MROUND((B12+C12)/2,0.5)) | E12: =IF(ISBLANK(D12),"",IF(Ввод!$B$1<1,"P<1 мм — вне диапазона (A7.2)",748.1*IF(Ввод!$B$1>=2,(5.994295-0.972546*LOG10(Ввод!$B$1))/(2663.129-95.76*LOG10(Ввод!$B$1)),(6.761559-0.987672*LOG10(Ввод!$B$1))/(3000.538-43.00*LOG10(Ввод!$B$1)))/(1/(D12+273.1)+0.3861*IF(Ввод!$B$1>=2,(5.994295-0.972546*LOG10(Ввод!$B$1))/(2663.129-95.76*LOG10(Ввод!$B$1)),(6.761559-0.987672*LOG10(Ввод!$B$1))/(3000.538-43.00*LOG10(Ввод!$B$1)))-0.00051606)-273.1)) | F12: =IF(OR(ISBLANK(E12),ISBLANK(E13)),"",IF(Ввод!$B$1<=10,(1-LOG10(Ввод!$B$1))*2.9+LOG10(Ввод!$B$1)*2.8,2.8)*(EXP(1)*EXP(IF(Ввод!$B$1<=10,(1-LOG10(Ввод!$B$1))*0.439+LOG10(Ввод!$B$1)*0.24,0.24)+IF(Ввод!$B$1<=10,(1-LOG10(Ввод!$B$1))*0.241+LOG10(Ввод!$B$1)*0.35,0.35)*LN(1.8*(ABS(E13-E11)/(A13-A11)))))/1.8) | G12: =IF(OR(ISBLANK(E12),ISBLANK(E13)),"",IF(Ввод!$B$1<=10,(1-LOG10(Ввод!$B$1))*3.3+LOG10(Ввод!$B$1)*3.2,3.2)*(EXP(1)*EXP(IF(Ввод!$B$1<=10,(1-LOG10(Ввод!$B$1))*1.338+LOG10(Ввод!$B$1)*1.415,1.415)+IF(Ввод!$B$1<=10,(1-LOG10(Ввод!$B$1))*0.639+LOG10(Ввод!$B$1)*0.409,0.409)*LN(1.8*(ABS(E13-E11)/(A13-A11)))))/1.8) | H12: =IF(OR(ISBLANK(B12),ISBLANK(C12)),"",ABS(B12-C12)) | I12: =(1/SQRT(2))*SQRT(G12^2-F12^2/2) | J12: =0.84*G12 | K12: =IF(OR(ISBLANK(B12),ISBLANK(C12)),"НЕ РАССЧИТАНО",IF(AND(ISNUMBER(H12),ISNUMBER(F12)),IF(H12<=F12,"OK","НЕ СООТВЕТСТВУЕТ"),"НЕ РАССЧИТАНО"))
A13: 55 | B13: ='Ввод'!C15 | C13: ='Ввод'!D15 | D13: =IF(OR(ISBLANK(B13),ISBLANK(C13)),B13,MROUND((B13+C13)/2,0.5)) | E13: =IF(ISBLANK(D13),"",IF(Ввод!$B$1<1,"P<1 мм — вне диапазона (A7.2)",748.1*IF(Ввод!$B$1>=2,(5.994295-0.972546*LOG10(Ввод!$B$1))/(2663.129-95.76*LOG10(Ввод!$B$1)),(6.761559-0.987672*LOG10(Ввод!$B$1))/(3000.538-43.00*LOG10(Ввод!$B$1)))/(1/(D13+273.1)+0.3861*IF(Ввод!$B$1>=2,(5.994295-0.972546*LOG10(Ввод!$B$1))/(2663.129-95.76*LOG10(Ввод!$B$1)),(6.761559-0.987672*LOG10(Ввод!$B$1))/(3000.538-43.00*LOG10(Ввод!$B$1)))-0.00051606)-273.1)) | F13: =IF(OR(ISBLANK(E13),ISBLANK(E14)),"",IF(Ввод!$B$1<=10,(1-LOG10(Ввод!$B$1))*3.0+LOG10(Ввод!$B$1)*2.9,2.9)*(EXP(1)*EXP(IF(Ввод!$B$1<=10,(1-LOG10(Ввод!$B$1))*0.439+LOG10(Ввод!$B$1)*0.24,0.24)+IF(Ввод!$B$1<=10,(1-LOG10(Ввод!$B$1))*0.241+LOG10(Ввод!$B$1)*0.35,0.35)*LN(1.8*(ABS(E14-E12)/(A14-A12)))))/1.8) | G13: =IF(OR(ISBLANK(E13),ISBLANK(E14)),"",IF(Ввод!$B$1<=10,(1-LOG10(Ввод!$B$1))*3.3+LOG10(Ввод!$B$1)*3.1,3.1)*(EXP(1)*EXP(IF(Ввод!$B$1<=10,(1-LOG10(Ввод!$B$1))*0.815+LOG10(Ввод!$B$1)*1.19,1.19)+IF(Ввод!$B$1<=10,(1-LOG10(Ввод!$B$1))*0.639+LOG10(Ввод!$B$1)*0.409,0.409)*LN(1.8*(ABS(E14-E12)/(A14-A12)))))/1.8) | H13: =IF(OR(ISBLANK(B13),ISBLANK(C13)),"",ABS(B13-C13)) | I13: =(1/SQRT(2))*SQRT(G13^2-F13^2/2) | J13: =0.84*G13 | K13: =IF(OR(ISBLANK(B13),ISBLANK(C13)),"НЕ РАССЧИТАНО",IF(AND(ISNUMBER(H13),ISNUMBER(F13)),IF(H13<=F13,"OK","НЕ СООТВЕТСТВУЕТ"),"НЕ РАССЧИТАНО"))
A14: 60 | B14: ='Ввод'!C16 | C14: ='Ввод'!D16 | D14: =IF(OR(ISBLANK(B14),ISBLANK(C14)),B14,MROUND((B14+C14)/2,0.5)) | E14: =IF(ISBLANK(D14),"",IF(Ввод!$B$1<1,"P<1 мм — вне диапазона (A7.2)",748.1*IF(Ввод!$B$1>=2,(5.994295-0.972546*LOG10(Ввод!$B$1))/(2663.129-95.76*LOG10(Ввод!$B$1)),(6.761559-0.987672*LOG10(Ввод!$B$1))/(3000.538-43.00*LOG10(Ввод!$B$1)))/(1/(D14+273.1)+0.3861*IF(Ввод!$B$1>=2,(5.994295-0.972546*LOG10(Ввод!$B$1))/(2663.129-95.76*LOG10(Ввод!$B$1)),(6.761559-0.987672*LOG10(Ввод!$B$1))/(3000.538-43.00*LOG10(Ввод!$B$1)))-0.00051606)-273.1)) | F14: =IF(OR(ISBLANK(E14),ISBLANK(E15)),"",IF(Ввод!$B$1<=10,(1-LOG10(Ввод!$B$1))*3.0+LOG10(Ввод!$B$1)*2.9,2.9)*(EXP(1)*EXP(IF(Ввод!$B$1<=10,(1-LOG10(Ввод!$B$1))*0.439+LOG10(Ввод!$B$1)*0.24,0.24)+IF(Ввод!$B$1<=10,(1-LOG10(Ввод!$B$1))*0.241+LOG10(Ввод!$B$1)*0.35,0.35)*LN(1.8*(ABS(E15-E13)/(A15-A13)))))/1.8) | G14: =IF(OR(ISBLANK(E14),ISBLANK(E15)),"",IF(Ввод!$B$1<=10,(1-LOG10(Ввод!$B$1))*3.3+LOG10(Ввод!$B$1)*3.1,3.1)*(EXP(1)*EXP(IF(Ввод!$B$1<=10,(1-LOG10(Ввод!$B$1))*0.815+LOG10(Ввод!$B$1)*1.19,1.19)+IF(Ввод!$B$1<=10,(1-LOG10(Ввод!$B$1))*0.639+LOG10(Ввод!$B$1)*0.409,0.409)*LN(1.8*(ABS(E15-E13)/(A15-A13)))))/1.8) | H14: =IF(OR(ISBLANK(B14),ISBLANK(C14)),"",ABS(B14-C14)) | I14: =(1/SQRT(2))*SQRT(G14^2-F14^2/2) | J14: =0.84*G14 | K14: =IF(OR(ISBLANK(B14),ISBLANK(C14)),"НЕ РАССЧИТАНО",IF(AND(ISNUMBER(H14),ISNUMBER(F14)),IF(H14<=F14,"OK","НЕ СООТВЕТСТВУЕТ"),"НЕ РАССЧИТАНО"))
A15: 65 | B15: ='Ввод'!C17 | C15: ='Ввод'!D17 | D15: =IF(OR(ISBLANK(B15),ISBLANK(C15)),B15,MROUND((B15+C15)/2,0.5)) | E15: =IF(ISBLANK(D15),"",IF(Ввод!$B$1<1,"P<1 мм — вне диапазона (A7.2)",748.1*IF(Ввод!$B$1>=2,(5.994295-0.972546*LOG10(Ввод!$B$1))/(2663.129-95.76*LOG10(Ввод!$B$1)),(6.761559-0.987672*LOG10(Ввод!$B$1))/(3000.538-43.00*LOG10(Ввод!$B$1)))/(1/(D15+273.1)+0.3861*IF(Ввод!$B$1>=2,(5.994295-0.972546*LOG10(Ввод!$B$1))/(2663.129-95.76*LOG10(Ввод!$B$1)),(6.761559-0.987672*LOG10(Ввод!$B$1))/(3000.538-43.00*LOG10(Ввод!$B$1)))-0.00051606)-273.1)) | F15: =IF(OR(ISBLANK(E15),ISBLANK(E16)),"",IF(Ввод!$B$1<=10,(1-LOG10(Ввод!$B$1))*3.0+LOG10(Ввод!$B$1)*2.9,2.9)*(EXP(1)*EXP(IF(Ввод!$B$1<=10,(1-LOG10(Ввод!$B$1))*0.439+LOG10(Ввод!$B$1)*0.24,0.24)+IF(Ввод!$B$1<=10,(1-LOG10(Ввод!$B$1))*0.241+LOG10(Ввод!$B$1)*0.35,0.35)*LN(1.8*(ABS(E16-E14)/(A16-A14)))))/1.8) | G15: =IF(OR(ISBLANK(E15),ISBLANK(E16)),"",IF(Ввод!$B$1<=10,(1-LOG10(Ввод!$B$1))*3.3+LOG10(Ввод!$B$1)*3.1,3.1)*(EXP(1)*EXP(IF(Ввод!$B$1<=10,(1-LOG10(Ввод!$B$1))*0.815+LOG10(Ввод!$B$1)*1.19,1.19)+IF(Ввод!$B$1<=10,(1-LOG10(Ввод!$B$1))*0.639+LOG10(Ввод!$B$1)*0.409,0.409)*LN(1.8*(ABS(E16-E14)/(A16-A14)))))/1.8) | H15: =IF(OR(ISBLANK(B15),ISBLANK(C15)),"",ABS(B15-C15)) | I15: =(1/SQRT(2))*SQRT(G15^2-F15^2/2) | J15: =0.84*G15 | K15: =IF(OR(ISBLANK(B15),ISBLANK(C15)),"НЕ РАССЧИТАНО",IF(AND(ISNUMBER(H15),ISNUMBER(F15)),IF(H15<=F15,"OK","НЕ СООТВЕТСТВУЕТ"),"НЕ РАССЧИТАНО"))
A16: 70 | B16: ='Ввод'!C18 | C16: ='Ввод'!D18 | D16: =IF(OR(ISBLANK(B16),ISBLANK(C16)),B16,MROUND((B16+C16)/2,0.5)) | E16: =IF(ISBLANK(D16),"",IF(Ввод!$B$1<1,"P<1 мм — вне диапазона (A7.2)",748.1*IF(Ввод!$B$1>=2,(5.994295-0.972546*LOG10(Ввод!$B$1))/(2663.129-95.76*LOG10(Ввод!$B$1)),(6.761559-0.987672*LOG10(Ввод!$B$1))/(3000.538-43.00*LOG10(Ввод!$B$1)))/(1/(D16+273.1)+0.3861*IF(Ввод!$B$1>=2,(5.994295-0.972546*LOG10(Ввод!$B$1))/(2663.129-95.76*LOG10(Ввод!$B$1)),(6.761559-0.987672*LOG10(Ввод!$B$1))/(3000.538-43.00*LOG10(Ввод!$B$1)))-0.00051606)-273.1)) | F16: =IF(OR(ISBLANK(E16),ISBLANK(E17)),"",IF(Ввод!$B$1<=10,(1-LOG10(Ввод!$B$1))*3.0+LOG10(Ввод!$B$1)*2.9,2.9)*(EXP(1)*EXP(IF(Ввод!$B$1<=10,(1-LOG10(Ввод!$B$1))*0.439+LOG10(Ввод!$B$1)*0.24,0.24)+IF(Ввод!$B$1<=10,(1-LOG10(Ввод!$B$1))*0.241+LOG10(Ввод!$B$1)*0.35,0.35)*LN(1.8*(ABS(E17-E15)/(A17-A15)))))/1.8) | G16: =IF(OR(ISBLANK(E16),ISBLANK(E17)),"",IF(Ввод!$B$1<=10,(1-LOG10(Ввод!$B$1))*3.3+LOG10(Ввод!$B$1)*3.1,3.1)*(EXP(1)*EXP(IF(Ввод!$B$1<=10,(1-LOG10(Ввод!$B$1))*0.815+LOG10(Ввод!$B$1)*1.19,1.19)+IF(Ввод!$B$1<=10,(1-LOG10(Ввод!$B$1))*0.639+LOG10(Ввод!$B$1)*0.409,0.409)*LN(1.8*(ABS(E17-E15)/(A17-A15)))))/1.8) | H16: =IF(OR(ISBLANK(B16),ISBLANK(C16)),"",ABS(B16-C16)) | I16: =(1/SQRT(2))*SQRT(G16^2-F16^2/2) | J16: =0.84*G16 | K16: =IF(OR(ISBLANK(B16),ISBLANK(C16)),"НЕ РАССЧИТАНО",IF(AND(ISNUMBER(H16),ISNUMBER(F16)),IF(H16<=F16,"OK","НЕ СООТВЕТСТВУЕТ"),"НЕ РАССЧИТАНО"))
A17: 75 | B17: ='Ввод'!C19 | C17: ='Ввод'!D19 | D17: =IF(OR(ISBLANK(B17),ISBLANK(C17)),B17,MROUND((B17+C17)/2,0.5)) | E17: =IF(ISBLANK(D17),"",IF(Ввод!$B$1<1,"P<1 мм — вне диапазона (A7.2)",748.1*IF(Ввод!$B$1>=2,(5.994295-0.972546*LOG10(Ввод!$B$1))/(2663.129-95.76*LOG10(Ввод!$B$1)),(6.761559-0.987672*LOG10(Ввод!$B$1))/(3000.538-43.00*LOG10(Ввод!$B$1)))/(1/(D17+273.1)+0.3861*IF(Ввод!$B$1>=2,(5.994295-0.972546*LOG10(Ввод!$B$1))/(2663.129-95.76*LOG10(Ввод!$B$1)),(6.761559-0.987672*LOG10(Ввод!$B$1))/(3000.538-43.00*LOG10(Ввод!$B$1)))-0.00051606)-273.1)) | F17: =IF(OR(ISBLANK(E17),ISBLANK(E18)),"",IF(Ввод!$B$1<=10,(1-LOG10(Ввод!$B$1))*3.0+LOG10(Ввод!$B$1)*2.9,2.9)*(EXP(1)*EXP(IF(Ввод!$B$1<=10,(1-LOG10(Ввод!$B$1))*0.439+LOG10(Ввод!$B$1)*0.24,0.24)+IF(Ввод!$B$1<=10,(1-LOG10(Ввод!$B$1))*0.241+LOG10(Ввод!$B$1)*0.35,0.35)*LN(1.8*(ABS(E18-E16)/(A18-A16)))))/1.8) | G17: =IF(OR(ISBLANK(E17),ISBLANK(E18)),"",IF(Ввод!$B$1<=10,(1-LOG10(Ввод!$B$1))*3.3+LOG10(Ввод!$B$1)*3.1,3.1)*(EXP(1)*EXP(IF(Ввод!$B$1<=10,(1-LOG10(Ввод!$B$1))*0.815+LOG10(Ввод!$B$1)*1.19,1.19)+IF(Ввод!$B$1<=10,(1-LOG10(Ввод!$B$1))*0.639+LOG10(Ввод!$B$1)*0.409,0.409)*LN(1.8*(ABS(E18-E16)/(A18-A16)))))/1.8) | H17: =IF(OR(ISBLANK(B17),ISBLANK(C17)),"",ABS(B17-C17)) | I17: =(1/SQRT(2))*SQRT(G17^2-F17^2/2) | J17: =0.84*G17 | K17: =IF(OR(ISBLANK(B17),ISBLANK(C17)),"НЕ РАССЧИТАНО",IF(AND(ISNUMBER(H17),ISNUMBER(F17)),IF(H17<=F17,"OK","НЕ СООТВЕТСТВУЕТ"),"НЕ РАССЧИТАНО"))
A18: 80 | B18: ='Ввод'!C20 | C18: ='Ввод'!D20 | D18: =IF(OR(ISBLANK(B18),ISBLANK(C18)),B18,MROUND((B18+C18)/2,0.5)) | E18: =IF(ISBLANK(D18),"",IF(Ввод!$B$1<1,"P<1 мм — вне диапазона (A7.2)",748.1*IF(Ввод!$B$1>=2,(5.994295-0.972546*LOG10(Ввод!$B$1))/(2663.129-95.76*LOG10(Ввод!$B$1)),(6.761559-0.987672*LOG10(Ввод!$B$1))/(3000.538-43.00*LOG10(Ввод!$B$1)))/(1/(D18+273.1)+0.3861*IF(Ввод!$B$1>=2,(5.994295-0.972546*LOG10(Ввод!$B$1))/(2663.129-95.76*LOG10(Ввод!$B$1)),(6.761559-0.987672*LOG10(Ввод!$B$1))/(3000.538-43.00*LOG10(Ввод!$B$1)))-0.00051606)-273.1)) | F18: =IF(OR(ISBLANK(E18),ISBLANK(E19)),"",IF(Ввод!$B$1<=10,(1-LOG10(Ввод!$B$1))*3.0+LOG10(Ввод!$B$1)*2.9,2.9)*(EXP(1)*EXP(IF(Ввод!$B$1<=10,(1-LOG10(Ввод!$B$1))*0.439+LOG10(Ввод!$B$1)*0.24,0.24)+IF(Ввод!$B$1<=10,(1-LOG10(Ввод!$B$1))*0.241+LOG10(Ввод!$B$1)*0.35,0.35)*LN(1.8*(ABS(E19-E17)/(A19-A17)))))/1.8) | G18: =IF(OR(ISBLANK(E18),ISBLANK(E19)),"",IF(Ввод!$B$1<=10,(1-LOG10(Ввод!$B$1))*3.3+LOG10(Ввод!$B$1)*3.1,3.1)*(EXP(1)*EXP(IF(Ввод!$B$1<=10,(1-LOG10(Ввод!$B$1))*0.815+LOG10(Ввод!$B$1)*1.19,1.19)+IF(Ввод!$B$1<=10,(1-LOG10(Ввод!$B$1))*0.639+LOG10(Ввод!$B$1)*0.409,0.409)*LN(1.8*(ABS(E19-E17)/(A19-A17)))))/1.8) | H18: =IF(OR(ISBLANK(B18),ISBLANK(C18)),"",ABS(B18-C18)) | I18: =(1/SQRT(2))*SQRT(G18^2-F18^2/2) | J18: =0.84*G18 | K18: =IF(OR(ISBLANK(B18),ISBLANK(C18)),"НЕ РАССЧИТАНО",IF(AND(ISNUMBER(H18),ISNUMBER(F18)),IF(H18<=F18,"OK","НЕ СООТВЕТСТВУЕТ"),"НЕ РАССЧИТАНО"))
A19: 85 | B19: ='Ввод'!C21 | C19: ='Ввод'!D21 | D19: =IF(OR(ISBLANK(B19),ISBLANK(C19)),B19,MROUND((B19+C19)/2,0.5)) | E19: =IF(ISBLANK(D19),"",IF(Ввод!$B$1<1,"P<1 мм — вне диапазона (A7.2)",748.1*IF(Ввод!$B$1>=2,(5.994295-0.972546*LOG10(Ввод!$B$1))/(2663.129-95.76*LOG10(Ввод!$B$1)),(6.761559-0.987672*LOG10(Ввод!$B$1))/(3000.538-43.00*LOG10(Ввод!$B$1)))/(1/(D19+273.1)+0.3861*IF(Ввод!$B$1>=2,(5.994295-0.972546*LOG10(Ввод!$B$1))/(2663.129-95.76*LOG10(Ввод!$B$1)),(6.761559-0.987672*LOG10(Ввод!$B$1))/(3000.538-43.00*LOG10(Ввод!$B$1)))-0.00051606)-273.1)) | F19: =IF(OR(ISBLANK(E19),ISBLANK(E20)),"",IF(Ввод!$B$1<=10,(1-LOG10(Ввод!$B$1))*3.0+LOG10(Ввод!$B$1)*2.9,2.9)*(EXP(1)*EXP(IF(Ввод!$B$1<=10,(1-LOG10(Ввод!$B$1))*0.439+LOG10(Ввод!$B$1)*0.24,0.24)+IF(Ввод!$B$1<=10,(1-LOG10(Ввод!$B$1))*0.241+LOG10(Ввод!$B$1)*0.35,0.35)*LN(1.8*(ABS(E20-E18)/(A20-A18)))))/1.8) | G19: =IF(OR(ISBLANK(E19),ISBLANK(E20)),"",IF(Ввод!$B$1<=10,(1-LOG10(Ввод!$B$1))*3.3+LOG10(Ввод!$B$1)*3.1,3.1)*(EXP(1)*EXP(IF(Ввод!$B$1<=10,(1-LOG10(Ввод!$B$1))*0.815+LOG10(Ввод!$B$1)*1.19,1.19)+IF(Ввод!$B$1<=10,(1-LOG10(Ввод!$B$1))*0.639+LOG10(Ввод!$B$1)*0.409,0.409)*LN(1.8*(ABS(E20-E18)/(A20-A18)))))/1.8) | H19: =IF(OR(ISBLANK(B19),ISBLANK(C19)),"",ABS(B19-C19)) | I19: =(1/SQRT(2))*SQRT(G19^2-F19^2/2) | J19: =0.84*G19 | K19: =IF(OR(ISBLANK(B19),ISBLANK(C19)),"НЕ РАССЧИТАНО",IF(AND(ISNUMBER(H19),ISNUMBER(F19)),IF(H19<=F19,"OK","НЕ СООТВЕТСТВУЕТ"),"НЕ РАССЧИТАНО"))
A20: 90 | B20: ='Ввод'!C22 | C20: ='Ввод'!D22 | D20: =IF(OR(ISBLANK(B20),ISBLANK(C20)),B20,MROUND((B20+C20)/2,0.5)) | E20: =IF(ISBLANK(D20),"",IF(Ввод!$B$1<1,"P<1 мм — вне диапазона (A7.2)",748.1*IF(Ввод!$B$1>=2,(5.994295-0.972546*LOG10(Ввод!$B$1))/(2663.129-95.76*LOG10(Ввод!$B$1)),(6.761559-0.987672*LOG10(Ввод!$B$1))/(3000.538-43.00*LOG10(Ввод!$B$1)))/(1/(D20+273.1)+0.3861*IF(Ввод!$B$1>=2,(5.994295-0.972546*LOG10(Ввод!$B$1))/(2663.129-95.76*LOG10(Ввод!$B$1)),(6.761559-0.987672*LOG10(Ввод!$B$1))/(3000.538-43.00*LOG10(Ввод!$B$1)))-0.00051606)-273.1)) | F20: =IF(OR(ISBLANK(E20),ISBLANK(E21)),"",IF(Ввод!$B$1<=10,(1-LOG10(Ввод!$B$1))*3.0+LOG10(Ввод!$B$1)*2.9,2.9)*(EXP(1)*EXP(IF(Ввод!$B$1<=10,(1-LOG10(Ввод!$B$1))*0.439+LOG10(Ввод!$B$1)*0.24,0.24)+IF(Ввод!$B$1<=10,(1-LOG10(Ввод!$B$1))*0.241+LOG10(Ввод!$B$1)*0.35,0.35)*LN(1.8*(ABS(E21-E19)/(A21-A19)))))/1.8) | G20: =IF(OR(ISBLANK(E20),ISBLANK(E21)),"",IF(Ввод!$B$1<=10,(1-LOG10(Ввод!$B$1))*3.3+LOG10(Ввод!$B$1)*3.1,3.1)*(EXP(1)*EXP(IF(Ввод!$B$1<=10,(1-LOG10(Ввод!$B$1))*0.815+LOG10(Ввод!$B$1)*1.19,1.19)+IF(Ввод!$B$1<=10,(1-LOG10(Ввод!$B$1))*0.639+LOG10(Ввод!$B$1)*0.409,0.409)*LN(1.8*(ABS(E21-E19)/(A21-A19)))))/1.8) | H20: =IF(OR(ISBLANK(B20),ISBLANK(C20)),"",ABS(B20-C20)) | I20: =(1/SQRT(2))*SQRT(G20^2-F20^2/2) | J20: =0.84*G20 | K20: =IF(OR(ISBLANK(B20),ISBLANK(C20)),"НЕ РАССЧИТАНО",IF(AND(ISNUMBER(H20),ISNUMBER(F20)),IF(H20<=F20,"OK","НЕ СООТВЕТСТВУЕТ"),"НЕ РАССЧИТАНО"))
A21: 95 | B21: ='Ввод'!C23 | C21: ='Ввод'!D23 | D21: =IF(OR(ISBLANK(B21),ISBLANK(C21)),B21,MROUND((B21+C21)/2,0.5)) | E21: =IF(ISBLANK(D21),"",IF(Ввод!$B$1<1,"P<1 мм — вне диапазона (A7.2)",748.1*IF(Ввод!$B$1>=2,(5.994295-0.972546*LOG10(Ввод!$B$1))/(2663.129-95.76*LOG10(Ввод!$B$1)),(6.761559-0.987672*LOG10(Ввод!$B$1))/(3000.538-43.00*LOG10(Ввод!$B$1)))/(1/(D21+273.1)+0.3861*IF(Ввод!$B$1>=2,(5.994295-0.972546*LOG10(Ввод!$B$1))/(2663.129-95.76*LOG10(Ввод!$B$1)),(6.761559-0.987672*LOG10(Ввод!$B$1))/(3000.538-43.00*LOG10(Ввод!$B$1)))-0.00051606)-273.1)) | F21: =IF(OR(ISBLANK(E21),ISBLANK(E22)),"",IF(Ввод!$B$1<=10,(1-LOG10(Ввод!$B$1))*3.0+LOG10(Ввод!$B$1)*2.9,2.9)*(EXP(1)*EXP(IF(Ввод!$B$1<=10,(1-LOG10(Ввод!$B$1))*0.439+LOG10(Ввод!$B$1)*0.24,0.24)+IF(Ввод!$B$1<=10,(1-LOG10(Ввод!$B$1))*0.241+LOG10(Ввод!$B$1)*0.35,0.35)*LN(1.8*(ABS(E22-E20)/(A22-A20)))))/1.8) | G21: =IF(OR(ISBLANK(E21),ISBLANK(E22)),"",IF(Ввод!$B$1<=10,(1-LOG10(Ввод!$B$1))*3.3+LOG10(Ввод!$B$1)*3.1,3.1)*(EXP(1)*EXP(IF(Ввод!$B$1<=10,(1-LOG10(Ввод!$B$1))*0.815+LOG10(Ввод!$B$1)*1.19,1.19)+IF(Ввод!$B$1<=10,(1-LOG10(Ввод!$B$1))*0.639+LOG10(Ввод!$B$1)*0.409,0.409)*LN(1.8*(ABS(E22-E20)/(A22-A20)))))/1.8) | H21: =IF(OR(ISBLANK(B21),ISBLANK(C21)),"",ABS(B21-C21)) | I21: =(1/SQRT(2))*SQRT(G21^2-F21^2/2) | J21: =0.84*G21 | K21: =IF(OR(ISBLANK(B21),ISBLANK(C21)),"НЕ РАССЧИТАНО",IF(AND(ISNUMBER(H21),ISNUMBER(F21)),IF(H21<=F21,"OK","НЕ СООТВЕТСТВУЕТ"),"НЕ РАССЧИТАНО"))
A22: 100 | B22: ='Ввод'!C24 | C22: ='Ввод'!D24 | D22: =IF(OR(ISBLANK(B22),ISBLANK(C22)),B22,MROUND((B22+C22)/2,0.5)) | E22: =IF(ISBLANK(D22),"",IF(Ввод!$B$1<1,"P<1 мм — вне диапазона (A7.2)",748.1*IF(Ввод!$B$1>=2,(5.994295-0.972546*LOG10(Ввод!$B$1))/(2663.129-95.76*LOG10(Ввод!$B$1)),(6.761559-0.987672*LOG10(Ввод!$B$1))/(3000.538-43.00*LOG10(Ввод!$B$1)))/(1/(D22+273.1)+0.3861*IF(Ввод!$B$1>=2,(5.994295-0.972546*LOG10(Ввод!$B$1))/(2663.129-95.76*LOG10(Ввод!$B$1)),(6.761559-0.987672*LOG10(Ввод!$B$1))/(3000.538-43.00*LOG10(Ввод!$B$1)))-0.00051606)-273.1)) | F22: =IF(OR(ISBLANK(E22),ISBLANK(E22)),"",IF(Ввод!$B$1<=10,(1-LOG10(Ввод!$B$1))*2.9+LOG10(Ввод!$B$1)*2.8,2.8)*(EXP(1)*EXP(IF(Ввод!$B$1<=10,(1-LOG10(Ввод!$B$1))*0.718+LOG10(Ввод!$B$1)*1.521,1.521)+IF(Ввод!$B$1<=10,(1-LOG10(Ввод!$B$1))*0+LOG10(Ввод!$B$1)*0,0)*LN(1.8*(ABS(E22-E21)/5))))/1.8) | G22: =IF(OR(ISBLANK(E22),ISBLANK(E22)),"",IF(Ввод!$B$1<=10,(1-LOG10(Ввод!$B$1))*3.0+LOG10(Ввод!$B$1)*2.9,2.9)*(EXP(1)*EXP(IF(Ввод!$B$1<=10,(1-LOG10(Ввод!$B$1))*2.931+LOG10(Ввод!$B$1)*2.815,2.815)+IF(Ввод!$B$1<=10,(1-LOG10(Ввод!$B$1))*0+LOG10(Ввод!$B$1)*0,0)*LN(1.8*(ABS(E22-E21)/5))))/1.8) | H22: =IF(OR(ISBLANK(B22),ISBLANK(C22)),"",ABS(B22-C22)) | I22: =(1/SQRT(2))*SQRT(G22^2-F22^2/2) | J22: =0.84*G22 | K22: =IF(OR(ISBLANK(B22),ISBLANK(C22)),"НЕ РАССЧИТАНО",IF(AND(ISNUMBER(H22),ISNUMBER(F22)),IF(H22<=F22,"OK","НЕ СООТВЕТСТВУЕТ"),"НЕ РАССЧИТАНО"))
A25: ВЕТКА 2 — ЗАДАНЫ ТЕМПЕРАТУРЫ (независимая ветка, ввод на этом листе): температуры из НД (нормируемые при 760 мм рт.ст.) → T_фикс (что ФИКСИРОВАТЬ на термометре при текущем давлении) → лаборант вводит ОБЪЁМЫ двух параллелей (V1, V2) → Vср, % = (V1+V2)/2 / Ввод!$G$1 * 100 → второй график и вторая модель — D1160: пересчёт по AET, фиксация T не используется
A26: AET_цель, °C | B26: T_фикс (н/п для AET) | C26: — | D26: V1, мл (проба 1) | E26: V2, мл (проба 2) | F26: Vср, % | G26: r, % | H26: Статус | I26: ПОДСКАЗКА
B27: н/п (AET) | C27: — | F27: =IF(AND(ISNUMBER(D27),ISNUMBER(E27)),(D27+E27)/2/Ввод!$G$1*100,"") | G27: =IF(AND(ISNUMBER(D27),ISNUMBER(E27),F27<>0),ABS(D27-E27)/(D27+E27)*100,"") | H27: =IF(ISNUMBER(A27),IF(AND(ISNUMBER(D27),ISNUMBER(E27)),"OK","введи V1 и V2"),"—") | I27: ВЕТКА 2 (D1160): введите нужный AET (атмосферный эквивалент) в колонке A. Фиксация наблюдаемой T здесь не используется — кривая строится по AET. Объёмы двух параллелей — колонки D/E, Vср, % — колонка F.
B28: н/п (AET) | C28: — | F28: =IF(AND(ISNUMBER(D28),ISNUMBER(E28)),(D28+E28)/2/Ввод!$G$1*100,"") | G28: =IF(AND(ISNUMBER(D28),ISNUMBER(E28),F28<>0),ABS(D28-E28)/(D28+E28)*100,"") | H28: =IF(ISNUMBER(A28),IF(AND(ISNUMBER(D28),ISNUMBER(E28)),"OK","введи V1 и V2"),"—")
B29: н/п (AET) | C29: — | F29: =IF(AND(ISNUMBER(D29),ISNUMBER(E29)),(D29+E29)/2/Ввод!$G$1*100,"") | G29: =IF(AND(ISNUMBER(D29),ISNUMBER(E29),F29<>0),ABS(D29-E29)/(D29+E29)*100,"") | H29: =IF(ISNUMBER(A29),IF(AND(ISNUMBER(D29),ISNUMBER(E29)),"OK","введи V1 и V2"),"—")
B30: н/п (AET) | C30: — | F30: =IF(AND(ISNUMBER(D30),ISNUMBER(E30)),(D30+E30)/2/Ввод!$G$1*100,"") | G30: =IF(AND(ISNUMBER(D30),ISNUMBER(E30),F30<>0),ABS(D30-E30)/(D30+E30)*100,"") | H30: =IF(ISNUMBER(A30),IF(AND(ISNUMBER(D30),ISNUMBER(E30)),"OK","введи V1 и V2"),"—")
B31: н/п (AET) | C31: — | F31: =IF(AND(ISNUMBER(D31),ISNUMBER(E31)),(D31+E31)/2/Ввод!$G$1*100,"") | G31: =IF(AND(ISNUMBER(D31),ISNUMBER(E31),F31<>0),ABS(D31-E31)/(D31+E31)*100,"") | H31: =IF(ISNUMBER(A31),IF(AND(ISNUMBER(D31),ISNUMBER(E31)),"OK","введи V1 и V2"),"—")
B32: н/п (AET) | C32: — | F32: =IF(AND(ISNUMBER(D32),ISNUMBER(E32)),(D32+E32)/2/Ввод!$G$1*100,"") | G32: =IF(AND(ISNUMBER(D32),ISNUMBER(E32),F32<>0),ABS(D32-E32)/(D32+E32)*100,"") | H32: =IF(ISNUMBER(A32),IF(AND(ISNUMBER(D32),ISNUMBER(E32)),"OK","введи V1 и V2"),"—")
B33: н/п (AET) | C33: — | F33: =IF(AND(ISNUMBER(D33),ISNUMBER(E33)),(D33+E33)/2/Ввод!$G$1*100,"") | G33: =IF(AND(ISNUMBER(D33),ISNUMBER(E33),F33<>0),ABS(D33-E33)/(D33+E33)*100,"") | H33: =IF(ISNUMBER(A33),IF(AND(ISNUMBER(D33),ISNUMBER(E33)),"OK","введи V1 и V2"),"—")
B34: н/п (AET) | C34: — | F34: =IF(AND(ISNUMBER(D34),ISNUMBER(E34)),(D34+E34)/2/Ввод!$G$1*100,"") | G34: =IF(AND(ISNUMBER(D34),ISNUMBER(E34),F34<>0),ABS(D34-E34)/(D34+E34)*100,"") | H34: =IF(ISNUMBER(A34),IF(AND(ISNUMBER(D34),ISNUMBER(E34)),"OK","введи V1 и V2"),"—")
B35: н/п (AET) | C35: — | F35: =IF(AND(ISNUMBER(D35),ISNUMBER(E35)),(D35+E35)/2/Ввод!$G$1*100,"") | G35: =IF(AND(ISNUMBER(D35),ISNUMBER(E35),F35<>0),ABS(D35-E35)/(D35+E35)*100,"") | H35: =IF(ISNUMBER(A35),IF(AND(ISNUMBER(D35),ISNUMBER(E35)),"OK","введи V1 и V2"),"—")
B36: н/п (AET) | C36: — | F36: =IF(AND(ISNUMBER(D36),ISNUMBER(E36)),(D36+E36)/2/Ввод!$G$1*100,"") | G36: =IF(AND(ISNUMBER(D36),ISNUMBER(E36),F36<>0),ABS(D36-E36)/(D36+E36)*100,"") | H36: =IF(ISNUMBER(A36),IF(AND(ISNUMBER(D36),ISNUMBER(E36)),"OK","введи V1 и V2"),"—")
B37: н/п (AET) | C37: — | F37: =IF(AND(ISNUMBER(D37),ISNUMBER(E37)),(D37+E37)/2/Ввод!$G$1*100,"") | G37: =IF(AND(ISNUMBER(D37),ISNUMBER(E37),F37<>0),ABS(D37-E37)/(D37+E37)*100,"") | H37: =IF(ISNUMBER(A37),IF(AND(ISNUMBER(D37),ISNUMBER(E37)),"OK","введи V1 и V2"),"—")
B38: н/п (AET) | C38: — | F38: =IF(AND(ISNUMBER(D38),ISNUMBER(E38)),(D38+E38)/2/Ввод!$G$1*100,"") | G38: =IF(AND(ISNUMBER(D38),ISNUMBER(E38),F38<>0),ABS(D38-E38)/(D38+E38)*100,"") | H38: =IF(ISNUMBER(A38),IF(AND(ISNUMBER(D38),ISNUMBER(E38)),"OK","введи V1 и V2"),"—")
B39: н/п (AET) | C39: — | F39: =IF(AND(ISNUMBER(D39),ISNUMBER(E39)),(D39+E39)/2/Ввод!$G$1*100,"") | G39: =IF(AND(ISNUMBER(D39),ISNUMBER(E39),F39<>0),ABS(D39-E39)/(D39+E39)*100,"") | H39: =IF(ISNUMBER(A39),IF(AND(ISNUMBER(D39),ISNUMBER(E39)),"OK","введи V1 и V2"),"—")
... B47: н/п (AET) | C47: — | F47: =IF(AND(ISNUMBER(D47),ISNUMBER(E47)),(D47+E47)/2/Ввод!$G$1*100,"") | G47: =IF(AND(ISNUMBER(D47),ISNUMBER(E47),F47<>0),ABS(D47-E47)/(D47+E47)*100,"") | H47: =IF(ISNUMBER(A47),IF(AND(ISNUMBER(D47),ISNUMBER(E47)),"OK","введи V1 и V2"),"—")
A48: D1160: кривая строится по AET (Максвелл-Боннелл); заданная температура — AET, фиксация наблюдаемой T требует обратного AET — не применяется. Объёмы двух параллелей — V1/V2 (D/E), Vср, % — (F).
A50: АППРОКСИМАЦИЯ КРИВОЙ ВЕТКИ 1 КУБИЧЕСКИМ ПОЛИНОМОМ (T_corr = a3·V³+a2·V²+a1·V+a0; кривая НЕ линейна):
...

Sheet Итог
A1: ИТОГ расчёта D1160
A2: Давление, мм рт.ст. | B2: ='Ввод'!B1
A3: Объём образца, мл | B3: ='Ввод'!G1
A5: % отгона | B5: T1 | C5: T2 | D5: T_corr | E5: r | F5: R | G5: Статус
A6: ='Расчёт'!A2 | B6: ='Расчёт'!B2 | C6: ='Расчёт'!C2 | D6: ='Расчёт'!E2 | E6: ='Расчёт'!F2 | F6: ='Расчёт'!G2 | G6: ='Расчёт'!K2
A7: ='Расчёт'!A3 | B7: ='Расчёт'!B3 | C7: ='Расчёт'!C3 | D7: ='Расчёт'!E3 | E7: ='Расчёт'!F3 | F7: ='Расчёт'!G3 | G7: ='Расчёт'!K3
A8: ='Расчёт'!A4 | B8: ='Расчёт'!B4 | C8: ='Расчёт'!C4 | D8: ='Расчёт'!E4 | E8: ='Расчёт'!F4 | F8: ='Расчёт'!G4 | G8: ='Расчёт'!K4
A9: ='Расчёт'!A5 | B9: ='Расчёт'!B5 | C9: ='Расчёт'!C5 | D9: ='Расчёт'!E5 | E9: ='Расчёт'!F5 | F9: ='Расчёт'!G5 | G9: ='Расчёт'!K5
A10: ='Расчёт'!A6 | B10: ='Расчёт'!B6 | C10: ='Расчёт'!C6 | D10: ='Расчёт'!E6 | E10: ='Расчёт'!F6 | F10: ='Расчёт'!G6 | G10: ='Расчёт'!K6
A11: ='Расчёт'!A7 | B11: ='Расчёт'!B7 | C11: ='Расчёт'!C7 | D11: ='Расчёт'!E7 | E11: ='Расчёт'!F7 | F11: ='Расчёт'!G7 | G11: ='Расчёт'!K7
A12: ='Расчёт'!A8 | B12: ='Расчёт'!B8 | C12: ='Расчёт'!C8 | D12: ='Расчёт'!E8 | E12: ='Расчёт'!F8 | F12: ='Расчёт'!G8 | G12: ='Расчёт'!K8
A13: ='Расчёт'!A9 | B13: ='Расчёт'!B9 | C13: ='Расчёт'!C9 | D13: ='Расчёт'!E9 | E13: ='Расчёт'!F9 | F13: ='Расчёт'!G9 | G13: ='Расчёт'!K9
A14: ='Расчёт'!A10 | B14: ='Расчёт'!B10 | C14: ='Расчёт'!C10 | D14: ='Расчёт'!E10 | E14: ='Расчёт'!F10 | F14: ='Расчёт'!G10 | G14: ='Расчёт'!K10
A15: ='Расчёт'!A11 | B15: ='Расчёт'!B11 | C15: ='Расчёт'!C11 | D15: ='Расчёт'!E11 | E15: ='Расчёт'!F11 | F15: ='Расчёт'!G11 | G15: ='Расчёт'!K11
A16: ='Расчёт'!A12 | B16: ='Расчёт'!B12 | C16: ='Расчёт'!C12 | D16: ='Расчёт'!E12 | E16: ='Расчёт'!F12 | F16: ='Расчёт'!G12 | G16: ='Расчёт'!K12
A17: ='Расчёт'!A13 | B17: ='Расчёт'!B13 | C17: ='Расчёт'!C13 | D17: ='Расчёт'!E13 | E17: ='Расчёт'!F13 | F17: ='Расчёт'!G13 | G17: ='Расчёт'!K13
... A26: ='Расчёт'!A22 | B26: ='Расчёт'!B22 | C26: ='Расчёт'!C22 | D26: ='Расчёт'!E22 | E26: ='Расчёт'!F22 | F26: ='Расчёт'!G22 | G26: ='Расчёт'!K22
A28: Обратный пересчёт T->V (коррекция давления ДО) и V->T (коррекция ПОСЛЕ) — в листе «Расчёт»

Sheet График
A1: Графики дистилляции (D1160). Диаграмма 1 — Ветка 1 (% отгона → T_corr + полином); Диаграмма 2 — Ветка 2 (Vср, % → T_НД + полином).
A3: % отгона | B3: AET (эксперимент) | C3: T_полином (аппроксимация) | E3: Vср, % (Ветка 2) | F3: T_НД, °C (из НД, при 760) | G3: T_полином Ветки 2 (аппроксимация)
A4: ='Расчёт'!A2 | B4: ='Расчёт'!E2 | C4: ='Расчёт'!C54 | E4: ='Расчёт'!F27 | F4: ='Расчёт'!A27 | G4: ='Расчёт'!C81
A5: ='Расчёт'!A3 | B5: ='Расчёт'!E3 | C5: ='Расчёт'!C55 | E5: ='Расчёт'!F28 | F5: ='Расчёт'!A28 | G5: ='Расчёт'!C82
A6: ='Расчёт'!A4 | B6: ='Расчёт'!E4 | C6: ='Расчёт'!C56 | E6: ='Расчёт'!F29 | F6: ='Расчёт'!A29 | G6: ='Расчёт'!C83
A7: ='Расчёт'!A5 | B7: ='Расчёт'!E5 | C7: ='Расчёт'!C57 | E7: ='Расчёт'!F30 | F7: ='Расчёт'!A30 | G7: ='Расчёт'!C84
A8: ='Расчёт'!A6 | B8: ='Расчёт'!E6 | C8: ='Расчёт'!C58 | E8: ='Расчёт'!F31 | F8: ='Расчёт'!A31 | G8: ='Расчёт'!C85
A9: ='Расчёт'!A7 | B9: ='Расчёт'!E7 | C9: ='Расчёт'!C59 | E9: ='Расчёт'!F32 | F9: ='Расчёт'!A32 | G9: ='Расчёт'!C86
A10: ='Расчёт'!A8 | B10: ='Расчёт'!E8 | C10: ='Расчёт'!C60 | E10: ='Расчёт'!F33 | F10: ='Расчёт'!A33 | G10: ='Расчёт'!C87
A11: ='Расчёт'!A9 | B11: ='Расчёт'!E9 | C11: ='Расчёт'!C61 | E11: ='Расчёт'!F34 | F11: ='Расчёт'!A34 | G11: ='Расчёт'!C88
A12: ='Расчёт'!A10 | B12: ='Расчёт'!E10 | C12: ='Расчёт'!C62 | E12: ='Расчёт'!F35 | F12: ='Расчёт'!A35 | G12: ='Расчёт'!C89
A13: ='Расчёт'!A11 | B13: ='Расчёт'!E11 | C13: ='Расчёт'!C63 | E13: ='Расчёт'!F36 | F13: ='Расчёт'!A36 | G13: ='Расчёт'!C90
A14: ='Расчёт'!A12 | B14: ='Расчёт'!E12 | C14: ='Расчёт'!C64 | E14: ='Расчёт'!F37 | F14: ='Расчёт'!A37 | G14: ='Расчёт'!C91
A15: ='Расчёт'!A13 | B15: ='Расчёт'!E13 | C15: ='Расчёт'!C65 | E15: ='Расчёт'!F38 | F15: ='Расчёт'!A38 | G15: ='Расчёт'!C92
... A24: ='Расчёт'!A22 | B24: ='Расчёт'!E22 | C24: ='Расчёт'!C74 | E24: ='Расчёт'!F47 | F24: ='Расчёт'!A47 | G24: ='Расчёт'!C101
A26: R² (полином Ветки 1, из листа «Расчёт»): | B26: ='Расчёт'!B75 | E26: R² (полином Ветки 2, из листа «Расчёт»): | F26: ='Расчёт'!B102
A27: ВСПОМОГАТЕЛЬНАЯ ОБЛАСТЬ (Ветка 2): пары Vср → T_НД, собранные БЕЗ ПУСТОТ (для LINEST второй модели и второй диаграммы)
A28: Vср, % (без пустот) | B28: T_НД, °C (без пустот)
A29: =IFERROR(INDEX('Расчёт'!$F$27:$F$47,SMALL(IF(ISNUMBER('Расчёт'!$F$27:$F$47),ROW('Расчёт'!$F$27:$F$47)-ROW('Расчёт'!$F$27)+1),1)),"") | B29: =IFERROR(INDEX('Расчёт'!$A$27:$A$47,SMALL(IF(ISNUMBER('Расчёт'!$F$27:$F$47),ROW('Расчёт'!$F$27:$F$47)-ROW('Расчёт'!$F$27)+1),1)),"")
A30: =IFERROR(INDEX('Расчёт'!$F$27:$F$47,SMALL(IF(ISNUMBER('Расчёт'!$F$27:$F$47),ROW('Расчёт'!$F$27:$F$47)-ROW('Расчёт'!$F$27)+1),2)),"") | B30: =IFERROR(INDEX('Расчёт'!$A$27:$A$47,SMALL(IF(ISNUMBER('Расчёт'!$F$27:$F$47),ROW('Расчёт'!$F$27:$F$47)-ROW('Расчёт'!$F$27)+1),2)),"")
A31: =IFERROR(INDEX('Расчёт'!$F$27:$F$47,SMALL(IF(ISNUMBER('Расчёт'!$F$27:$F$47),ROW('Расчёт'!$F$27:$F$47)-ROW('Расчёт'!$F$27)+1),3)),"") | B31: =IFERROR(INDEX('Расчёт'!$A$27:$A$47,SMALL(IF(ISNUMBER('Расчёт'!$F$27:$F$47),ROW('Расчёт'!$F$27:$F$47)-ROW('Расчёт'!$F$27)+1),3)),"")
A32: =IFERROR(INDEX('Расчёт'!$F$27:$F$47,SMALL(IF(ISNUMBER('Расчёт'!$F$27:$F$47),ROW('Расчёт'!$F$27:$F$47)-ROW('Расчёт'!$F$27)+1),4)),"") | B32: =IFERROR(INDEX('Расчёт'!$A$27:$A$47,SMALL(IF(ISNUMBER('Расчёт'!$F$27:$F$47),ROW('Расчёт'!$F$27:$F$47)-ROW('Расчёт'!$F$27)+1),4)),"")
A33: =IFERROR(INDEX('Расчёт'!$F$27:$F$47,SMALL(IF(ISNUMBER('Расчёт'!$F$27:$F$47),ROW('Расчёт'!$F$27:$F$47)-ROW('Расчёт'!$F$27)+1),5)),"") | B33: =IFERROR(INDEX('Расчёт'!$A$27:$A$47,SMALL(IF(ISNUMBER('Расчёт'!$F$27:$F$47),ROW('Расчёт'!$F$27:$F$47)-ROW('Расчёт'!$F$27)+1),5)),"")
A34: =IFERROR(INDEX('Расчёт'!$F$27:$F$47,SMALL(IF(ISNUMBER('Расчёт'!$F$27:$F$47),ROW('Расчёт'!$F$27:$F$47)-ROW('Расчёт'!$F$27)+1),6)),"") | B34: =IFERROR(INDEX('Расчёт'!$A$27:$A$47,SMALL(IF(ISNUMBER('Расчёт'!$F$27:$F$47),ROW('Расчёт'!$F$27:$F$47)-ROW('Расчёт'!$F$27)+1),6)),"")
A35: =IFERROR(INDEX('Расчёт'!$F$27:$F$47,SMALL(IF(ISNUMBER('Расчёт'!$F$27:$F$47),ROW('Расчёт'!$F$27:$F$47)-ROW('Расчёт'!$F$27)+1),7)),"") | B35: =IFERROR(INDEX('Расчёт'!$A$27:$A$47,SMALL(IF(ISNUMBER('Расчёт'!$F$27:$F$47),ROW('Расчёт'!$F$27:$F$47)-ROW('Расчёт'!$F$27)+1),7)),"")
A36: =IFERROR(INDEX('Расчёт'!$F$27:$F$47,SMALL(IF(ISNUMBER('Расчёт'!$F$27:$F$47),ROW('Расчёт'!$F$27:$F$47)-ROW('Расчёт'!$F$27)+1),8)),"") | B36: =IFERROR(INDEX('Расчёт'!$A$27:$A$47,SMALL(IF(ISNUMBER('Расчёт'!$F$27:$F$47),ROW('Расчёт'!$F$27:$F$47)-ROW('Расчёт'!$F$27)+1),8)),"")
A37: =IFERROR(INDEX('Расчёт'!$F$27:$F$47,SMALL(IF(ISNUMBER('Расчёт'!$F$27:$F$47),ROW('Расчёт'!$F$27:$F$47)-ROW('Расчёт'!$F$27)+1),9)),"") | B37: =IFERROR(INDEX('Расчёт'!$A$27:$A$47,SMALL(IF(ISNUMBER('Расчёт'!$F$27:$F$47),ROW('Расчёт'!$F$27:$F$47)-ROW('Расчёт'!$F$27)+1),9)),"")
A38: =IFERROR(INDEX('Расчёт'!$F$27:$F$47,SMALL(IF(ISNUMBER('Расчёт'!$F$27:$F$47),ROW('Расчёт'!$F$27:$F$47)-ROW('Расчёт'!$F$27)+1),10)),"") | B38: =IFERROR(INDEX('Расчёт'!$A$27:$A$47,SMALL(IF(ISNUMBER('Расчёт'!$F$27:$F$47),ROW('Расчёт'!$F$27:$F$47)-ROW('Расчёт'!$F$27)+1),10)),"")
A39: =IFERROR(INDEX('Расчёт'!$F$27:$F$47,SMALL(IF(ISNUMBER('Расчёт'!$F$27:$F$47),ROW('Расчёт'!$F$27:$F$47)-ROW('Расчёт'!$F$27)+1),11)),"") | B39: =IFERROR(INDEX('Расчёт'!$A$27:$A$47,SMALL(IF(ISNUMBER('Расчёт'!$F$27:$F$47),ROW('Расчёт'!$F$27:$F$47)-ROW('Расчёт'!$F$27)+1),11)),"")
A40: =IFERROR(INDEX('Расчёт'!$F$27:$F$47,SMALL(IF(ISNUMBER('Расчёт'!$F$27:$F$47),ROW('Расчёт'!$F$27:$F$47)-ROW('Расчёт'!$F$27)+1),12)),"") | B40: =IFERROR(INDEX('Расчёт'!$A$27:$A$47,SMALL(IF(ISNUMBER('Расчёт'!$F$27:$F$47),ROW('Расчёт'!$F$27:$F$47)-ROW('Расчёт'!$F$27)+1),12)),"")
A41: =IFERROR(INDEX('Расчёт'!$F$27:$F$47,SMALL(IF(ISNUMBER('Расчёт'!$F$27:$F$47),ROW('Расчёт'!$F$27:$F$47)-ROW('Расчёт'!$F$27)+1),13)),"") | B41: =IFERROR(INDEX('Расчёт'!$A$27:$A$47,SMALL(IF(ISNUMBER('Расчёт'!$F$27:$F$47),ROW('Расчёт'!$F$27:$F$47)-ROW('Расчёт'!$F$27)+1),13)),"")
A42: =IFERROR(INDEX('Расчёт'!$F$27:$F$47,SMALL(IF(ISNUMBER('Расчёт'!$F$27:$F$47),ROW('Расчёт'!$F$27:$F$47)-ROW('Расчёт'!$F$27)+1),14)),"") | B42: =IFERROR(INDEX('Расчёт'!$A$27:$A$47,SMALL(IF(ISNUMBER('Расчёт'!$F$27:$F$47),ROW('Расчёт'!$F$27:$F$47)-ROW('Расчёт'!$F$27)+1),14)),"")
A43: =IFERROR(INDEX('Расчёт'!$F$27:$F$47,SMALL(IF(ISNUMBER('Расчёт'!$F$27:$F$47),ROW('Расчёт'!$F$27:$F$47)-ROW('Расчёт'!$F$27)+1),15)),"") | B43: =IFERROR(INDEX('Расчёт'!$A$27:$A$47,SMALL(IF(ISNUMBER('Расчёт'!$F$27:$F$47),ROW('Расчёт'!$F$27:$F$47)-ROW('Расчёт'!$F$27)+1),15)),"")
A44: =IFERROR(INDEX('Расчёт'!$F$27:$F$47,SMALL(IF(ISNUMBER('Расчёт'!$F$27:$F$47),ROW('Расчёт'!$F$27:$F$47)-ROW('Расчёт'!$F$27)+1),16)),"") | B44: =IFERROR(INDEX('Расчёт'!$A$27:$A$47,SMALL(IF(ISNUMBER('Расчёт'!$F$27:$F$47),ROW('Расчёт'!$F$27:$F$47)-ROW('Расчёт'!$F$27)+1),16)),"")
A45: =IFERROR(INDEX('Расчёт'!$F$27:$F$47,SMALL(IF(ISNUMBER('Расчёт'!$F$27:$F$47),ROW('Расчёт'!$F$27:$F$47)-ROW('Расчёт'!$F$27)+1),17)),"") | B45: =IFERROR(INDEX('Расчёт'!$A$27:$A$47,SMALL(IF(ISNUMBER('Расчёт'!$F$27:$F$47),ROW('Расчёт'!$F$27:$F$47)-ROW('Расчёт'!$F$27)+1),17)),"")
A46: =IFERROR(INDEX('Расчёт'!$F$27:$F$47,SMALL(IF(ISNUMBER('Расчёт'!$F$27:$F$47),ROW('Расчёт'!$F$27:$F$47)-ROW('Расчёт'!$F$27)+1),18)),"") | B46: =IFERROR(INDEX('Расчёт'!$A$27:$A$47,SMALL(IF(ISNUMBER('Расчёт'!$F$27:$F$47),ROW('Расчёт'!$F$27:$F$47)-ROW('Расчёт'!$F$27)+1),18)),"")
A47: =IFERROR(INDEX('Расчёт'!$F$27:$F$47,SMALL(IF(ISNUMBER('Расчёт'!$F$27:$F$47),ROW('Расчёт'!$F$27:$F$47)-ROW('Расчёт'!$F$27)+1),19)),"") | B47: =IFERROR(INDEX('Расчёт'!$A$27:$A$47,SMALL(IF(ISNUMBER('Расчёт'!$F$27:$F$47),ROW('Расчёт'!$F$27:$F$47)-ROW('Расчёт'!$F$27)+1),19)),"")
A48: =IFERROR(INDEX('Расчёт'!$F$27:$F$47,SMALL(IF(ISNUMBER('Расчёт'!$F$27:$F$47),ROW('Расчёт'!$F$27:$F$47)-ROW('Расчёт'!$F$27)+1),20)),"") | B48: =IFERROR(INDEX('Расчёт'!$A$27:$A$47,SMALL(IF(ISNUMBER('Расчёт'!$F$27:$F$47),ROW('Расчёт'!$F$27:$F$47)-ROW('Расчёт'!$F$27)+1),20)),"")
A49: =IFERROR(INDEX('Расчёт'!$F$27:$F$47,SMALL(IF(ISNUMBER('Расчёт'!$F$27:$F$47),ROW('Расчёт'!$F$27:$F$47)-ROW('Расчёт'!$F$27)+1),21)),"") | B49: =IFERROR(INDEX('Расчёт'!$A$27:$A$47,SMALL(IF(ISNUMBER('Расчёт'!$F$27:$F$47),ROW('Расчёт'!$F$27:$F$47)-ROW('Расчёт'!$F$27)+1),21)),"")
